Workbook
Name enum_ExchangeRateMethod: importDropDownContent!$A$2:$A$3
Name enum_gl_standard_import_voucher_status: importDropDownContent!$B$2:$B$5
Name refer_finbd.bd_allaccbodyref0: 参照!$C$3:$C$63
Name refer_fiepub.fiepub_accountbooktreeref1: 参照!$G$3:$G$61
Name refer_fiepub.epub_vouchertype_ref2: 参照!$K$3:$K$6
Name refer_bip_usercenter.bip_user_ref3: 参照!$O$3:$O$95
Name refer_ucfbasedoc.bd_currencytenantref4: 参照!$S$3:$S$3
Name refer_ucfbasedoc.bd_exchangeratetyperef5: 参照!$W$3:$W$4
Name refer_productcenter.aa_productunit6: 参照!$AA$3:$AA$37
Name refer_productcenter.aa_settlemethodref7: 参照!$AE$3:$AE$9

Sheet ReadMe
A1: Excel模板使用指南： 模板格式：请严格遵守表格中既定字段顺序，不得擅自调整或增减表头字段，以确保模板合法性。 数据类型：单元格内请输入文本格式的数据，以确保数值不会因excel软件转换丢失精度。 必填标识：带星号（*）的字段为必须填写项，请确保不遗漏。 引用档案：黄色背景字段为引用档案（参照），请填写参照名称或编码。 日期格式：建议使用“YYYY-MM-DD”格式（例如：2021-06-06）来输入日期，确保日期信息的标准化。 特殊字段说明：浅绿色背景字段用于确保数据的唯一性。若无特定业务唯一性要求，则默认使用系统生成的ID（手工码）。若子孙表中有浅蓝色背景的手工码，它是用于关联主表与子表数据的关联标识。 导入过滤：“✓”标记用于指示该行数据在导入过程中将被忽略。此标识常见于业务说明、属性说明或错误明细文件中，以避免重复或错误数据的导入。 国际化格式支持：下载模板时，若启用了“我的首选”功能，下载的模板将自动应用“首选项”的时区、数值、时间等格式设置。在导入数据时，系统将依据这些设置进行自动转换与存储。 总结：请遵循上述指南，以确保数据导入的顺利进行和结果的准确性。

Sheet 亿企凭证
B1: 日期 | C1: 凭证字号 | D1: 摘要 | E1: 科目 | F1: 借方金额 | G1: 贷方金额 | H1: 一级科目编码 | I1: 科目编码 | J1: 一级科目 | K1: 二级科目 | L1: 三级科目 | M1: 对应用友科目编码 | N1: 对应辅助核算类型 | O1: 对应辅助核算 | P1: *(单据头)账簿#编码 | Q1: (单据头)账簿#名称 | R1: *(单据头)日期 | S1: (单据头)期间 | T1: *(单据头)凭证字#编码 | U1: (单据头)凭证字#名称 | V1: *(单据头)凭证号 | W1: *系统码 | X1: *会计主体 | Y1: *账簿 | Z1: 账簿名称 | AA1: *会计期间 | AB1: *制单日期 | AC1: *凭证类型 | AD1: 凭证号 | AE1: 凭证摘要 | AF1: 制单人 | AG1: 制单人名称 | AH1: 附单据数 | AI1: 凭证标识 | AJ1: 结转标识 | AK1: 编码 | AL1: 系统码 | AM1: 分录号 | AN1: *科目 | AO1: 科目名称 | AP1: *摘要 | AQ1: *币种 | AR1: 借方原币金额 | AS1: 贷方原币金额 | AT1: 本币汇率类型 | AU1: 本币汇率折算方式 | AV1: 本币汇率 | AW1: 借方本币金额 | AX1: 贷方本币金额 | AY1: 计量单位 | AZ1: 计量单位名称 | BA1: 单价 | BB1: 借方数量 | BC1: 贷方数量 | BD1: 业务日期 | BE1: 结算方式 | BF1: 票据号 | BG1: 票据日期 | BH1: 银行对账码 | BI1: 核销号 | BJ1: 内部单位 | BK1: 现金流量主表项编码 | BL1: 现金流量附表项编码 | BM1: 现金流量项原币金额 | BN1: 现金流量项本币金额 | BO1: 部门_编码 | BP1: 部门_名称 | BQ1: 项目_编码 | BR1: 项目_名称 | BS1: 人员_编码 | BT1: 人员_名称 | BU1: 供应商_编码 | BV1: 供应商_名称 | BW1: 客户_编码 | BX1: 客户_名称 | BY1: 物料_编码 | BZ1: 物料_名称 | CA1: 物料分类_编码 | CB1: 物料分类_名称 | CC1: 成本中心_编码 | CD1: 成本中心_名称 | CE1: 业务伙伴_编码 | CF1: 业务伙伴_名称 | CG1: 利润中心_编码 | CH1: 利润中心_名称 | CI1: 业务活动类型_编码 | CJ1: 业务活动类型_名称 | CK1: 业务组织_编码 | CL1: 业务组织_名称 | CM1: 土地_编码 | CN1: 土地_名称 | CO1: 员工_编码 | CP1: 员工_名称 | CQ1: 会计商品_编码 | CR1: 会计商品_名称 | CS1: 内部核算单元_编码 | CT1: 内部核算单元_名称 | CU1: 费用项目_编码 | CV1: 费用项目_名称 | CW1: 银行账户_编码 | CX1: 银行账户_名称
A2: 昌邑泓澄水业有限公司 | B2: 2026-04-20 | C2: 记-001 | D2: 往来款,昌邑市城市建设发展投资集团有限公司 | E2: 100201 银行存款-工商银行3066 | F2: 390000 | H2: =LEFT(E2,4) -> 1002 | I2: =IFERROR(LEFT(E2,FIND(" ",E2)-1),E2) -> 100201 | J2: =LEFT(MID(E2,FIND(" ",E2)+1,LEN(E2)),FIND("-",MID(E2,FIND(" ",E2)+1,LEN(E2))&"-")-1) -> 银行存款 | K2: =IFERROR(MID(MID(E2,FIND(" ",E2)+1,LEN(E2)),FIND("-",MID(E2,FIND(" ",E2)+1,LEN(E2)))+1,IFERROR(FIND("-",MID(E2,FIND(" ",E2)+1,LEN(E2)),FIND("-",MID(E2,FIND(" ",E2)+1,LEN(E2)))+1),LEN(MID(E2,FIND(" ",E2)+1,LEN(E2)))+1)-FIND("-",MID(E2,FIND(" ",E2)+1,LEN(E2)))-1),"") -> 工商银行3066 | L2: =IFERROR(MID(MID(E2,FIND(" ",E2)+1,LEN(E2)),FIND("-",MID(E2,FIND(" ",E2)+1,LEN(E2)),FIND("-",MID(E2,FIND(" ",E2)+1,LEN(E2)))+1)+1,LEN(E2)),"") | M2: =IF(H2="1002",1002,VLOOKUP(I2,亿企科目!A:H,6,0)) -> 1002 | N2: =IFERROR(IF(H2="1002","银行账户",IF(H2="1123","供应商",VLOOKUP(I2,亿企科目!A:H,8,0))),"") -> 银行账户 | O2: =IF(N2=0,IF(M2="1002",K2,""),_xlfn.TEXTAFTER(E2,"-",-1)) -> 工商银行3066 | P2: =VLOOKUP(A2,账簿!B:C,2,0) -> 002022 | Q2: =VLOOKUP(P2,账簿!A:B,2,0) -> 昌邑泓澄水业有限公司 | W2: =X2&AB2&AD2 -> 0020222026-04-201 | X2: =P2 -> 002022 | Y2: =X2 -> 002022 | Z2: =Q2 -> 昌邑泓澄水业有限公司 | AA2: =LEFT(B2,7) -> 2026-04 | AB2: =B2 -> 2026-04-20 | AC2: 记 | AD2: =VALUE(_xlfn.TEXTAFTER(C2,"-")) -> 1 | AE2: =D2 -> 往来款,昌邑市城市建设发展投资集团有限公司 | AF2: 谭雅心 | AG2: 谭雅心 | AN2: =M2 -> 1002 | AP2: =D2 -> 往来款,昌邑市城市建设发展投资集团有限公司 | AQ2: CNY | AR2: =F2 -> 390000 | AS2: =G2 | AT2: 01 | AU2: * | AV2: 1 | AW2: =AR2 -> 390000 | AX2: =AS2 | BQ2: =IF(N2="项目",VLOOKUP(O2,项目!B:C,2,0),IF(K2="空项目",VLOOKUP(K2,项目!B:C,2,0),"")) | BR2: =IFERROR(VLOOKUP(BQ2,项目!A:B,2,0),"") | BU2: =IF(N2="供应商",VLOOKUP(O2,供应商!B:C,2,0),"") | BV2: =IFERROR(VLOOKUP(BU2,供应商!A:B,2,0),"") | BW2: =IF(N2="客户",VLOOKUP(O2,客户!B:C,2,0),"") | BX2: =IFERROR(VLOOKUP(BW2,客户!A:B,2,0),"") | CU2: =IF(N2="费用项目",VLOOKUP(O2,费用项目!B:C,2,0),"") | CV2: =IFERROR(VLOOKUP(CU2,费用项目!A:B,2,0),"") | CW2: =IF(N2="银行账户",VLOOKUP(O2,银行变二级!B:C,2,0),"") -> 工商银行3066 | CX2: =IFERROR(VLOOKUP(O2,银行变二级!A:B,2,0),"") -> 工商银行3066
A3: 昌邑泓澄水业有限公司 | B3: 2026-04-20 | C3: 记-001 | D3: 往来款,昌邑市城市建设发展投资集团有限公司 | E3: 122108 其他应收款-单位-昌邑市城市建设发展投资集团有限公司 | G3: 390000 | H3: =LEFT(E3,4) -> 1221 | I3: =IFERROR(LEFT(E3,FIND(" ",E3)-1),E3) -> 122108 | J3: =LEFT(MID(E3,FIND(" ",E3)+1,LEN(E3)),FIND("-",MID(E3,FIND(" ",E3)+1,LEN(E3))&"-")-1) -> 其他应收款 | K3: =IFERROR(MID(MID(E3,FIND(" ",E3)+1,LEN(E3)),FIND("-",MID(E3,FIND(" ",E3)+1,LEN(E3)))+1,IFERROR(FIND("-",MID(E3,FIND(" ",E3)+1,LEN(E3)),FIND("-",MID(E3,FIND(" ",E3)+1,LEN(E3)))+1),LEN(MID(E3,FIND(" ",E3)+1,LEN(E3)))+1)-FIND("-",MID(E3,FIND(" ",E3)+1,LEN(E3)))-1),"") -> 单位 | L3: =IFERROR(MID(MID(E3,FIND(" ",E3)+1,LEN(E3)),FIND("-",MID(E3,FIND(" ",E3)+1,LEN(E3)),FIND("-",MID(E3,FIND(" ",E3)+1,LEN(E3)))+1)+1,LEN(E3)),"") -> 昌邑市城市建设发展投资集团有限公司 | M3: =IFERROR(IF(H3="1002",1002,VLOOKUP(I3,亿企科目!A:H,6,0)),VLOOKUP(H3,亿企科目!A:G,6,0)) -> 122102 | N3: =IFERROR(IF(H3="1002","银行账户",IF(H3="1123","供应商",VLOOKUP(I3,亿企科目!A:H,8,0))),"") -> 客户 | O3: =IF(N3=0,IF(M3="1002",K3,""),_xlfn.TEXTAFTER(E3,"-",-1)) -> 昌邑市城市建设发展投资集团有限公司 | P3: =VLOOKUP(A3,账簿!B:C,2,0) -> 002022 | Q3: =VLOOKUP(P3,账簿!A:B,2,0) -> 昌邑泓澄水业有限公司 | W3: =X3&AB3&AD3 -> 0020222026-04-201 | X3: =P3 -> 002022 | Y3: =X3 -> 002022 | Z3: =Q3 -> 昌邑泓澄水业有限公司 | AA3: =LEFT(B3,7) -> 2026-04 | AB3: =B3 -> 2026-04-20 | AC3: 记 | AD3: =VALUE(_xlfn.TEXTAFTER(C3,"-")) -> 1 | AE3: =D3 -> 往来款,昌邑市城市建设发展投资集团有限公司 | AF3: 谭雅心 | AG3: 谭雅心 | AN3: =M3 -> 122102 | AP3: =D3 -> 往来款,昌邑市城市建设发展投资集团有限公司 | AQ3: CNY | AR3: =F3 | AS3: =G3 -> 390000 | AT3: 01 | AU3: * | AV3: 1 | AW3: =AR3 | AX3: =AS3 -> 390000 | BQ3: =IF(N3="项目",VLOOKUP(O3,项目!B:C,2,0),IF(K3="空项目",VLOOKUP(K3,项目!B:C,2,0),"")) | BR3: =IFERROR(VLOOKUP(BQ3,项目!A:B,2,0),"") | BU3: =IF(N3="供应商",VLOOKUP(O3,供应商!B:C,2,0),"") | BV3: =IFERROR(VLOOKUP(BU3,供应商!A:B,2,0),"") | BW3: =IF(N3="客户",VLOOKUP(O3,客户!B:C,2,0),"") -> 002 | BX3: =IFERROR(VLOOKUP(BW3,客户!A:B,2,0),"") -> 昌邑市城市建设发展投资集团有限公司 | CU3: =IF(N3="费用项目",VLOOKUP(O3,费用项目!B:C,2,0),"") | CV3: =IFERROR(VLOOKUP(CU3,费用项目!A:B,2,0),"") | CW3: =IF(N3="银行账户",VLOOKUP(O3,银行变二级!B:C,2,0),"") | CX3: =IFERROR(VLOOKUP(O3,银行变二级!A:B,2,0),"")
A4: 昌邑泓澄水业有限公司 | B4: 2026-04-20 | C4: 记-002 | D4: 往来款,昌邑市昌宜投资有限公司 | E4: 100201 银行存款-工商银行3066 | F4: 20000000 | H4: =LEFT(E4,4) -> 1002 | I4: =IFERROR(LEFT(E4,FIND(" ",E4)-1),E4) -> 100201 | J4: =LEFT(MID(E4,FIND(" ",E4)+1,LEN(E4)),FIND("-",MID(E4,FIND(" ",E4)+1,LEN(E4))&"-")-1) -> 银行存款 | K4: =IFERROR(MID(MID(E4,FIND(" ",E4)+1,LEN(E4)),FIND("-",MID(E4,FIND(" ",E4)+1,LEN(E4)))+1,IFERROR(FIND("-",MID(E4,FIND(" ",E4)+1,LEN(E4)),FIND("-",MID(E4,FIND(" ",E4)+1,LEN(E4)))+1),LEN(MID(E4,FIND(" ",E4)+1,LEN(E4)))+1)-FIND("-",MID(E4,FIND(" ",E4)+1,LEN(E4)))-1),"") -> 工商银行3066 | L4: =IFERROR(MID(MID(E4,FIND(" ",E4)+1,LEN(E4)),FIND("-",MID(E4,FIND(" ",E4)+1,LEN(E4)),FIND("-",MID(E4,FIND(" ",E4)+1,LEN(E4)))+1)+1,LEN(E4)),"") | M4: =IFERROR(IF(H4="1002",1002,VLOOKUP(I4,亿企科目!A:H,6,0)),VLOOKUP(H4,亿企科目!A:G,6,0)) -> 1002 | N4: =IFERROR(IF(H4="1002","银行账户",IF(H4="1123","供应商",VLOOKUP(I4,亿企科目!A:H,8,0))),"") -> 银行账户 | O4: =IF(N4=0,IF(M4="1002",K4,""),_xlfn.TEXTAFTER(E4,"-",-1)) -> 工商银行3066 | P4: =VLOOKUP(A4,账簿!B:C,2,0) -> 002022 | Q4: =VLOOKUP(P4,账簿!A:B,2,0) -> 昌邑泓澄水业有限公司 | W4: =X4&AB4&AD4 -> 0020222026-04-202 | X4: =P4 -> 002022 | Y4: =X4 -> 002022 | Z4: =Q4 -> 昌邑泓澄水业有限公司 | AA4: =LEFT(B4,7) -> 2026-04 | AB4: =B4 -> 2026-04-20 | AC4: 记 | AD4: =VALUE(_xlfn.TEXTAFTER(C4,"-")) -> 2 | AE4: =D4 -> 往来款,昌邑市昌宜投资有限公司 | AF4: 谭雅心 | AG4: 谭雅心 | AN4: =M4 -> 1002 | AP4: =D4 -> 往来款,昌邑市昌宜投资有限公司 | AQ4: CNY | AR4: =F4 -> 20000000 | AS4: =G4 | AT4: 01 | AU4: * | AV4: 1 | AW4: =AR4 -> 20000000 | AX4: =AS4 | BQ4: =IF(N4="项目",VLOOKUP(O4,项目!B:C,2,0),IF(K4="空项目",VLOOKUP(K4,项目!B:C,2,0),"")) | BR4: =IFERROR(VLOOKUP(BQ4,项目!A:B,2,0),"") | BU4: =IF(N4="供应商",VLOOKUP(O4,供应商!B:C,2,0),"") | BV4: =IFERROR(VLOOKUP(BU4,供应商!A:B,2,0),"") | BW4: =IF(N4="客户",VLOOKUP(O4,客户!B:C,2,0),"") | BX4: =IFERROR(VLOOKUP(BW4,客户!A:B,2,0),"") | CU4: =IF(N4="费用项目",VLOOKUP(O4,费用项目!B:C,2,0),"") | CV4: =IFERROR(VLOOKUP(CU4,费用项目!A:B,2,0),"") | CW4: =IF(N4="银行账户",VLOOKUP(O4,银行变二级!B:C,2,0),"") -> 工商银行3066 | CX4: =IFERROR(VLOOKUP(O4,银行变二级!A:B,2,0),"") -> 工商银行3066
A5: 昌邑泓澄水业有限公司 | B5: 2026-04-20 | C5: 记-002 | D5: 往来款,昌邑市昌宜投资有限公司 | E5: 122108 其他应收款-单位-昌邑市昌宜投资有限公司 | G5: 20000000 | H5: =LEFT(E5,4) -> 1221 | I5: =IFERROR(LEFT(E5,FIND(" ",E5)-1),E5) -> 122108 | J5: =LEFT(MID(E5,FIND(" ",E5)+1,LEN(E5)),FIND("-",MID(E5,FIND(" ",E5)+1,LEN(E5))&"-")-1) -> 其他应收款 | K5: =IFERROR(MID(MID(E5,FIND(" ",E5)+1,LEN(E5)),FIND("-",MID(E5,FIND(" ",E5)+1,LEN(E5)))+1,IFERROR(FIND("-",MID(E5,FIND(" ",E5)+1,LEN(E5)),FIND("-",MID(E5,FIND(" ",E5)+1,LEN(E5)))+1),LEN(MID(E5,FIND(" ",E5)+1,LEN(E5)))+1)-FIND("-",MID(E5,FIND(" ",E5)+1,LEN(E5)))-1),"") -> 单位 | L5: =IFERROR(MID(MID(E5,FIND(" ",E5)+1,LEN(E5)),FIND("-",MID(E5,FIND(" ",E5)+1,LEN(E5)),FIND("-",MID(E5,FIND(" ",E5)+1,LEN(E5)))+1)+1,LEN(E5)),"") -> 昌邑市昌宜投资有限公司 | M5: =IFERROR(IF(H5="1002",1002,VLOOKUP(I5,亿企科目!A:H,6,0)),VLOOKUP(H5,亿企科目!A:G,6,0)) -> 122102 | N5: =IFERROR(IF(H5="1002","银行账户",IF(H5="1123","供应商",VLOOKUP(I5,亿企科目!A:H,8,0))),"") -> 客户 | O5: =IF(N5=0,IF(M5="1002",K5,""),_xlfn.TEXTAFTER(E5,"-",-1)) -> 昌邑市昌宜投资有限公司 | P5: =VLOOKUP(A5,账簿!B:C,2,0) -> 002022 | Q5: =VLOOKUP(P5,账簿!A:B,2,0) -> 昌邑泓澄水业有限公司 | W5: =X5&AB5&AD5 -> 0020222026-04-202 | X5: =P5 -> 002022 | Y5: =X5 -> 002022 | Z5: =Q5 -> 昌邑泓澄水业有限公司 | AA5: =LEFT(B5,7) -> 2026-04 | AB5: =B5 -> 2026-04-20 | AC5: 记 | AD5: =VALUE(_xlfn.TEXTAFTER(C5,"-")) -> 2 | AE5: =D5 -> 往来款,昌邑市昌宜投资有限公司 | AF5: 谭雅心 | AG5: 谭雅心 | AN5: =M5 -> 122102 | AP5: =D5 -> 往来款,昌邑市昌宜投资有限公司 | AQ5: CNY | AR5: =F5 | AS5: =G5 -> 20000000 | AT5: 01 | AU5: * | AV5: 1 | AW5: =AR5 | AX5: =AS5 -> 20000000 | BQ5: =IF(N5="项目",VLOOKUP(O5,项目!B:C,2,0),IF(K5="空项目",VLOOKUP(K5,项目!B:C,2,0),"")) | BR5: =IFERROR(VLOOKUP(BQ5,项目!A:B,2,0),"") | BU5: =IF(N5="供应商",VLOOKUP(O5,供应商!B:C,2,0),"") | BV5: =IFERROR(VLOOKUP(BU5,供应商!A:B,2,0),"") | BW5: =IF(N5="客户",VLOOKUP(O5,客户!B:C,2,0),"") -> 003019 | BX5: =IFERROR(VLOOKUP(BW5,客户!A:B,2,0),"") -> 昌邑市昌宜投资有限公司 | CU5: =IF(N5="费用项目",VLOOKUP(O5,费用项目!B:C,2,0),"") | CV5: =IFERROR(VLOOKUP(CU5,费用项目!A:B,2,0),"") | CW5: =IF(N5="银行账户",VLOOKUP(O5,银行变二级!B:C,2,0),"") | CX5: =IFERROR(VLOOKUP(O5,银行变二级!A:B,2,0),"")
A6: 昌邑泓澄水业有限公司 | B6: 2026-04-20 | C6: 记-003 | D6: 海洋水业公司并购,青岛天合易辉贸易有限公司 | E6: 151101 长期股权投资-投资成本-青岛天合易辉贸易有限公司 | F6: 14285900 | H6: =LEFT(E6,4) -> 1511 | I6: =IFERROR(LEFT(E6,FIND(" ",E6)-1),E6) -> 151101 | J6: =LEFT(MID(E6,FIND(" ",E6)+1,LEN(E6)),FIND("-",MID(E6,FIND(" ",E6)+1,LEN(E6))&"-")-1) -> 长期股权投资 | K6: =IFERROR(MID(MID(E6,FIND(" ",E6)+1,LEN(E6)),FIND("-",MID(E6,FIND(" ",E6)+1,LEN(E6)))+1,IFERROR(FIND("-",MID(E6,FIND(" ",E6)+1,LEN(E6)),FIND("-",MID(E6,FIND(" ",E6)+1,LEN(E6)))+1),LEN(MID(E6,FIND(" ",E6)+1,LEN(E6)))+1)-FIND("-",MID(E6,FIND(" ",E6)+1,LEN(E6)))-1),"") -> 投资成本 | L6: =IFERROR(MID(MID(E6,FIND(" ",E6)+1,LEN(E6)),FIND("-",MID(E6,FIND(" ",E6)+1,LEN(E6)),FIND("-",MID(E6,FIND(" ",E6)+1,LEN(E6)))+1)+1,LEN(E6)),"") -> 青岛天合易辉贸易有限公司 | M6: =IFERROR(IF(H6="1002",1002,VLOOKUP(I6,亿企科目!A:H,6,0)),VLOOKUP(H6,亿企科目!A:G,6,0)) -> 151101 | N6: =IFERROR(IF(H6="1002","银行账户",IF(H6="1123","供应商",VLOOKUP(I6,亿企科目!A:H,8,0))),"") -> 客户 | O6: =IF(N6=0,IF(M6="1002",K6,""),_xlfn.TEXTAFTER(E6,"-",-1)) -> 青岛天合易辉贸易有限公司 | P6: =VLOOKUP(A6,账簿!B:C,2,0) -> 002022 | Q6: =VLOOKUP(P6,账簿!A:B,2,0) -> 昌邑泓澄水业有限公司 | W6: =X6&AB6&AD6 -> 0020222026-04-203 | X6: =P6 -> 002022 | Y6: =X6 -> 002022 | Z6: =Q6 -> 昌邑泓澄水业有限公司 | AA6: =LEFT(B6,7) -> 2026-04 | AB6: =B6 -> 2026-04-20 | AC6: 记 | AD6: =VALUE(_xlfn.TEXTAFTER(C6,"-")) -> 3 | AE6: =D6 -> 海洋水业公司并购,青岛天合易辉贸易有限公司 | AF6: 谭雅心 | AG6: 谭雅心 | AN6: =M6 -> 151101 | AP6: =D6 -> 海洋水业公司并购,青岛天合易辉贸易有限公司 | AQ6: CNY | AR6: =F6 -> 14285900 | AS6: =G6 | AT6: 01 | AU6: * | AV6: 1 | AW6: =AR6 -> 14285900 | AX6: =AS6 | BQ6: =IF(N6="项目",VLOOKUP(O6,项目!B:C,2,0),IF(K6="空项目",VLOOKUP(K6,项目!B:C,2,0),"")) | BR6: =IFERROR(VLOOKUP(BQ6,项目!A:B,2,0),"") | BU6: =IF(N6="供应商",VLOOKUP(O6,供应商!B:C,2,0),"") | BV6: =IFERROR(VLOOKUP(BU6,供应商!A:B,2,0),"") | BW6: =IF(N6="客户",VLOOKUP(O6,客户!B:C,2,0),"") -> 0020006 | BX6: =IFERROR(VLOOKUP(BW6,客户!A:B,2,0),"") -> 青岛天合易辉贸易有限公司 | CU6: =IF(N6="费用项目",VLOOKUP(O6,费用项目!B:C,2,0),"") | CV6: =IFERROR(VLOOKUP(CU6,费用项目!A:B,2,0),"") | CW6: =IF(N6="银行账户",VLOOKUP(O6,银行变二级!B:C,2,0),"") | CX6: =IFERROR(VLOOKUP(O6,银行变二级!A:B,2,0),"")
A7: 昌邑泓澄水业有限公司 | B7: 2026-04-20 | C7: 记-003 | D7: 海洋水业公司并购,青岛天合易辉贸易有限公司 | E7: 100201 银行存款-工商银行3066 | G7: 14285900 | H7: =LEFT(E7,4) -> 1002 | I7: =IFERROR(LEFT(E7,FIND(" ",E7)-1),E7) -> 100201 | J7: =LEFT(MID(E7,FIND(" ",E7)+1,LEN(E7)),FIND("-",MID(E7,FIND(" ",E7)+1,LEN(E7))&"-")-1) -> 银行存款 | K7: =IFERROR(MID(MID(E7,FIND(" ",E7)+1,LEN(E7)),FIND("-",MID(E7,FIND(" ",E7)+1,LEN(E7)))+1,IFERROR(FIND("-",MID(E7,FIND(" ",E7)+1,LEN(E7)),FIND("-",MID(E7,FIND(" ",E7)+1,LEN(E7)))+1),LEN(MID(E7,FIND(" ",E7)+1,LEN(E7)))+1)-FIND("-",MID(E7,FIND(" ",E7)+1,LEN(E7)))-1),"") -> 工商银行3066 | L7: =IFERROR(MID(MID(E7,FIND(" ",E7)+1,LEN(E7)),FIND("-",MID(E7,FIND(" ",E7)+1,LEN(E7)),FIND("-",MID(E7,FIND(" ",E7)+1,LEN(E7)))+1)+1,LEN(E7)),"") | M7: =IFERROR(IF(H7="1002",1002,VLOOKUP(I7,亿企科目!A:H,6,0)),VLOOKUP(H7,亿企科目!A:G,6,0)) -> 1002 | N7: =IFERROR(IF(H7="1002","银行账户",IF(H7="1123","供应商",VLOOKUP(I7,亿企科目!A:H,8,0))),"") -> 银行账户 | O7: =IF(N7=0,IF(M7="1002",K7,""),_xlfn.TEXTAFTER(E7,"-",-1)) -> 工商银行3066 | P7: =VLOOKUP(A7,账簿!B:C,2,0) -> 002022 | Q7: =VLOOKUP(P7,账簿!A:B,2,0) -> 昌邑泓澄水业有限公司 | W7: =X7&AB7&AD7 -> 0020222026-04-203 | X7: =P7 -> 002022 | Y7: =X7 -> 002022 | Z7: =Q7 -> 昌邑泓澄水业有限公司 | AA7: =LEFT(B7,7) -> 2026-04 | AB7: =B7 -> 2026-04-20 | AC7: 记 | AD7: =VALUE(_xlfn.TEXTAFTER(C7,"-")) -> 3 | AE7: =D7 -> 海洋水业公司并购,青岛天合易辉贸易有限公司 | AF7: 谭雅心 | AG7: 谭雅心 | AN7: =M7 -> 1002 | AP7: =D7 -> 海洋水业公司并购,青岛天合易辉贸易有限公司 | AQ7: CNY | AR7: =F7 | AS7: =G7 -> 14285900 | AT7: 01 | AU7: * | AV7: 1 | AW7: =AR7 | AX7: =AS7 -> 14285900 | BQ7: =IF(N7="项目",VLOOKUP(O7,项目!B:C,2,0),IF(K7="空项目",VLOOKUP(K7,项目!B:C,2,0),"")) | BR7: =IFERROR(VLOOKUP(BQ7,项目!A:B,2,0),"") | BU7: =IF(N7="供应商",VLOOKUP(O7,供应商!B:C,2,0),"") | BV7: =IFERROR(VLOOKUP(BU7,供应商!A:B,2,0),"") | BW7: =IF(N7="客户",VLOOKUP(O7,客户!B:C,2,0),"") | BX7: =IFERROR(VLOOKUP(BW7,客户!A:B,2,0),"") | CU7: =IF(N7="费用项目",VLOOKUP(O7,费用项目!B:C,2,0),"") | CV7: =IFERROR(VLOOKUP(CU7,费用项目!A:B,2,0),"") | CW7: =IF(N7="银行账户",VLOOKUP(O7,银行变二级!B:C,2,0),"") -> 工商银行3066 | CX7: =IFERROR(VLOOKUP(O7,银行变二级!A:B,2,0),"") -> 工商银行3066
A8: 昌邑泓澄水业有限公司 | B8: 2026-04-20 | C8: 记-004 | D8: 海洋水业公司并购,范光华 | E8: 151101 长期股权投资-投资成本-范光华 | F8: 5714100 | H8: =LEFT(E8,4) -> 1511 | I8: =IFERROR(LEFT(E8,FIND(" ",E8)-1),E8) -> 151101 | J8: =LEFT(MID(E8,FIND(" ",E8)+1,LEN(E8)),FIND("-",MID(E8,FIND(" ",E8)+1,LEN(E8))&"-")-1) -> 长期股权投资 | K8: =IFERROR(MID(MID(E8,FIND(" ",E8)+1,LEN(E8)),FIND("-",MID(E8,FIND(" ",E8)+1,LEN(E8)))+1,IFERROR(FIND("-",MID(E8,FIND(" ",E8)+1,LEN(E8)),FIND("-",MID(E8,FIND(" ",E8)+1,LEN(E8)))+1),LEN(MID(E8,FIND(" ",E8)+1,LEN(E8)))+1)-FIND("-",MID(E8,FIND(" ",E8)+1,LEN(E8)))-1),"") -> 投资成本 | L8: =IFERROR(MID(MID(E8,FIND(" ",E8)+1,LEN(E8)),FIND("-",MID(E8,FIND(" ",E8)+1,LEN(E8)),FIND("-",MID(E8,FIND(" ",E8)+1,LEN(E8)))+1)+1,LEN(E8)),"") -> 范光华 | M8: =IFERROR(IF(H8="1002",1002,VLOOKUP(I8,亿企科目!A:H,6,0)),VLOOKUP(H8,亿企科目!A:G,6,0)) -> 151101 | N8: =IFERROR(IF(H8="1002","银行账户",IF(H8="1123","供应商",VLOOKUP(I8,亿企科目!A:H,8,0))),"") -> 客户 | O8: =IF(N8=0,IF(M8="1002",K8,""),_xlfn.TEXTAFTER(E8,"-",-1)) -> 范光华 | P8: =VLOOKUP(A8,账簿!B:C,2,0) -> 002022 | Q8: =VLOOKUP(P8,账簿!A:B,2,0) -> 昌邑泓澄水业有限公司 | W8: =X8&AB8&AD8 -> 0020222026-04-204 | X8: =P8 -> 002022 | Y8: =X8 -> 002022 | Z8: =Q8 -> 昌邑泓澄水业有限公司 | AA8: =LEFT(B8,7) -> 2026-04 | AB8: =B8 -> 2026-04-20 | AC8: 记 | AD8: =VALUE(_xlfn.TEXTAFTER(C8,"-")) -> 4 | AE8: =D8 -> 海洋水业公司并购,范光华 | AF8: 谭雅心 | AG8: 谭雅心 | AN8: =M8 -> 151101 | AP8: =D8 -> 海洋水业公司并购,范光华 | AQ8: CNY | AR8: =F8 -> 5714100 | AS8: =G8 | AT8: 01 | AU8: * | AV8: 1 | AW8: =AR8 -> 5714100 | AX8: =AS8 | BQ8: =IF(N8="项目",VLOOKUP(O8,项目!B:C,2,0),IF(K8="空项目",VLOOKUP(K8,项目!B:C,2,0),"")) | BR8: =IFERROR(VLOOKUP(BQ8,项目!A:B,2,0),"") | BU8: =IF(N8="供应商",VLOOKUP(O8,供应商!B:C,2,0),"") | BV8: =IFERROR(VLOOKUP(BU8,供应商!A:B,2,0),"") | BW8: =IF(N8="客户",VLOOKUP(O8,客户!B:C,2,0),"") -> 0030001 | BX8: =IFERROR(VLOOKUP(BW8,客户!A:B,2,0),"") -> 范光华 | CU8: =IF(N8="费用项目",VLOOKUP(O8,费用项目!B:C,2,0),"") | CV8: =IFERROR(VLOOKUP(CU8,费用项目!A:B,2,0),"") | CW8: =IF(N8="银行账户",VLOOKUP(O8,银行变二级!B:C,2,0),"") | CX8: =IFERROR(VLOOKUP(O8,银行变二级!A:B,2,0),"")
A9: 昌邑泓澄水业有限公司 | B9: 2026-04-20 | C9: 记-004 | D9: 海洋水业公司并购,范光华 | E9: 100201 银行存款-工商银行3066 | G9: 5714100 | H9: =LEFT(E9,4) -> 1002 | I9: =IFERROR(LEFT(E9,FIND(" ",E9)-1),E9) -> 100201 | J9: =LEFT(MID(E9,FIND(" ",E9)+1,LEN(E9)),FIND("-",MID(E9,FIND(" ",E9)+1,LEN(E9))&"-")-1) -> 银行存款 | K9: =IFERROR(MID(MID(E9,FIND(" ",E9)+1,LEN(E9)),FIND("-",MID(E9,FIND(" ",E9)+1,LEN(E9)))+1,IFERROR(FIND("-",MID(E9,FIND(" ",E9)+1,LEN(E9)),FIND("-",MID(E9,FIND(" ",E9)+1,LEN(E9)))+1),LEN(MID(E9,FIND(" ",E9)+1,LEN(E9)))+1)-FIND("-",MID(E9,FIND(" ",E9)+1,LEN(E9)))-1),"") -> 工商银行3066 | L9: =IFERROR(MID(MID(E9,FIND(" ",E9)+1,LEN(E9)),FIND("-",MID(E9,FIND(" ",E9)+1,LEN(E9)),FIND("-",MID(E9,FIND(" ",E9)+1,LEN(E9)))+1)+1,LEN(E9)),"") | M9: =IFERROR(IF(H9="1002",1002,VLOOKUP(I9,亿企科目!A:H,6,0)),VLOOKUP(H9,亿企科目!A:G,6,0)) -> 1002 | N9: =IFERROR(IF(H9="1002","银行账户",IF(H9="1123","供应商",VLOOKUP(I9,亿企科目!A:H,8,0))),"") -> 银行账户 | O9: =IF(N9=0,IF(M9="1002",K9,""),_xlfn.TEXTAFTER(E9,"-",-1)) -> 工商银行3066 | P9: =VLOOKUP(A9,账簿!B:C,2,0) -> 002022 | Q9: =VLOOKUP(P9,账簿!A:B,2,0) -> 昌邑泓澄水业有限公司 | W9: =X9&AB9&AD9 -> 0020222026-04-204 | X9: =P9 -> 002022 | Y9: =X9 -> 002022 | Z9: =Q9 -> 昌邑泓澄水业有限公司 | AA9: =LEFT(B9,7) -> 2026-04 | AB9: =B9 -> 2026-04-20 | AC9: 记 | AD9: =VALUE(_xlfn.TEXTAFTER(C9,"-")) -> 4 | AE9: =D9 -> 海洋水业公司并购,范光华 | AF9: 谭雅心 | AG9: 谭雅心 | AN9: =M9 -> 1002 | AP9: =D9 -> 海洋水业公司并购,范光华 | AQ9: CNY | AR9: =F9 | AS9: =G9 -> 5714100 | AT9: 01 | AU9: * | AV9: 1 | AW9: =AR9 | AX9: =AS9 -> 5714100 | BQ9: =IF(N9="项目",VLOOKUP(O9,项目!B:C,2,0),IF(K9="空项目",VLOOKUP(K9,项目!B:C,2,0),"")) | BR9: =IFERROR(VLOOKUP(BQ9,项目!A:B,2,0),"") | BU9: =IF(N9="供应商",VLOOKUP(O9,供应商!B:C,2,0),"") | BV9: =IFERROR(VLOOKUP(BU9,供应商!A:B,2,0),"") | BW9: =IF(N9="客户",VLOOKUP(O9,客户!B:C,2,0),"") | BX9: =IFERROR(VLOOKUP(BW9,客户!A:B,2,0),"") | CU9: =IF(N9="费用项目",VLOOKUP(O9,费用项目!B:C,2,0),"") | CV9: =IFERROR(VLOOKUP(CU9,费用项目!A:B,2,0),"") | CW9: =IF(N9="银行账户",VLOOKUP(O9,银行变二级!B:C,2,0),"") -> 工商银行3066 | CX9: =IFERROR(VLOOKUP(O9,银行变二级!A:B,2,0),"") -> 工商银行3066
A10: 昌邑泓澄水业有限公司 | B10: 2026-04-21 | C10: 记-005 | D10: 对公贷款利息支付,中长期并购贷款利息收入 | E10: 6603 财务费用-利息支出 | F10: 370500.01 | H10: =LEFT(E10,4) -> 6603 | I10: =IFERROR(LEFT(E10,FIND(" ",E10)-1),E10) -> 6603 | J10: =LEFT(MID(E10,FIND(" ",E10)+1,LEN(E10)),FIND("-",MID(E10,FIND(" ",E10)+1,LEN(E10))&"-")-1) -> 财务费用 | K10: =IFERROR(MID(MID(E10,FIND(" ",E10)+1,LEN(E10)),FIND("-",MID(E10,FIND(" ",E10)+1,LEN(E10)))+1,IFERROR(FIND("-",MID(E10,FIND(" ",E10)+1,LEN(E10)),FIND("-",MID(E10,FIND(" ",E10)+1,LEN(E10)))+1),LEN(MID(E10,FIND(" ",E10)+1,LEN(E10)))+1)-FIND("-",MID(E10,FIND(" ",E10)+1,LEN(E10)))-1),"") -> 利息支出 | L10: =IFERROR(MID(MID(E10,FIND(" ",E10)+1,LEN(E10)),FIND("-",MID(E10,FIND(" ",E10)+1,LEN(E10)),FIND("-",MID(E10,FIND(" ",E10)+1,LEN(E10)))+1)+1,LEN(E10)),"") | M10: =IFERROR(IF(H10="1002",1002,VLOOKUP(I10,亿企科目!A:H,6,0)),VLOOKUP(H10,亿企科目!A:G,6,0)) -> 6603 | N10: =IFERROR(IF(H10="1002","银行账户",IF(H10="1123","供应商",VLOOKUP(I10,亿企科目!A:H,8,0))),"") -> 费用项目 | O10: =IF(N10=0,IF(M10="1002",K10,""),_xlfn.TEXTAFTER(E10,"-",-1)) -> 利息支出 | P10: =VLOOKUP(A10,账簿!B:C,2,0) -> 002022 | Q10: =VLOOKUP(P10,账簿!A:B,2,0) -> 昌邑泓澄水业有限公司 | W10: =X10&AB10&AD10 -> 0020222026-04-215 | X10: =P10 -> 002022 | Y10: =X10 -> 002022 | Z10: =Q10 -> 昌邑泓澄水业有限公司 | AA10: =LEFT(B10,7) -> 2026-04 | AB10: =B10 -> 2026-04-21 | AC10: 记 | AD10: =VALUE(_xlfn.TEXTAFTER(C10,"-")) -> 5 | AE10: =D10 -> 对公贷款利息支付,中长期并购贷款利息收入 | AF10: 谭雅心 | AG10: 谭雅心 | AN10: =M10 -> 6603 | AP10: =D10 -> 对公贷款利息支付,中长期并购贷款利息收入 | AQ10: CNY | AR10: =F10 -> 370500.01 | AS10: =G10 | AT10: 01 | AU10: * | AV10: 1 | AW10: =AR10 -> 370500.01 | AX10: =AS10 | BQ10: =IF(N10="项目",VLOOKUP(O10,项目!B:C,2,0),IF(K10="空项目",VLOOKUP(K10,项目!B:C,2,0),"")) | BR10: =IFERROR(VLOOKUP(BQ10,项目!A:B,2,0),"") | BU10: =IF(N10="供应商",VLOOKUP(O10,供应商!B:C,2,0),"") | BV10: =IFERROR(VLOOKUP(BU10,供应商!A:B,2,0),"") | BW10: =IF(N10="客户",VLOOKUP(O10,客户!B:C,2,0),"") | BX10: =IFERROR(VLOOKUP(BW10,客户!A:B,2,0),"") | CU10: =IF(N10="费用项目",VLOOKUP(O10,费用项目!B:C,2,0),"") -> 660302 | CV10: =IFERROR(VLOOKUP(CU10,费用项目!A:B,2,0),"") -> 利息支出 | CW10: =IF(N10="银行账户",VLOOKUP(O10,银行变二级!B:C,2,0),"") | CX10: =IFERROR(VLOOKUP(O10,银行变二级!A:B,2,0),"")
A11: 昌邑泓澄水业有限公司 | B11: 2026-04-21 | C11: 记-005 | D11: 对公贷款利息支付,中长期并购贷款利息收入 | E11: 100201 银行存款-工商银行3066 | G11: 370500.01 | H11: =LEFT(E11,4) -> 1002 | I11: =IFERROR(LEFT(E11,FIND(" ",E11)-1),E11) -> 100201 | J11: =LEFT(MID(E11,FIND(" ",E11)+1,LEN(E11)),FIND("-",MID(E11,FIND(" ",E11)+1,LEN(E11))&"-")-1) -> 银行存款 | K11: =IFERROR(MID(MID(E11,FIND(" ",E11)+1,LEN(E11)),FIND("-",MID(E11,FIND(" ",E11)+1,LEN(E11)))+1,IFERROR(FIND("-",MID(E11,FIND(" ",E11)+1,LEN(E11)),FIND("-",MID(E11,FIND(" ",E11)+1,LEN(E11)))+1),LEN(MID(E11,FIND(" ",E11)+1,LEN(E11)))+1)-FIND("-",MID(E11,FIND(" ",E11)+1,LEN(E11)))-1),"") -> 工商银行3066 | L11: =IFERROR(MID(MID(E11,FIND(" ",E11)+1,LEN(E11)),FIND("-",MID(E11,FIND(" ",E11)+1,LEN(E11)),FIND("-",MID(E11,FIND(" ",E11)+1,LEN(E11)))+1)+1,LEN(E11)),"") | M11: =IFERROR(IF(H11="1002",1002,VLOOKUP(I11,亿企科目!A:H,6,0)),VLOOKUP(H11,亿企科目!A:G,6,0)) -> 1002 | N11: =IFERROR(IF(H11="1002","银行账户",IF(H11="1123","供应商",VLOOKUP(I11,亿企科目!A:H,8,0))),"") -> 银行账户 | O11: =IF(N11=0,IF(M11="1002",K11,""),_xlfn.TEXTAFTER(E11,"-",-1)) -> 工商银行3066 | P11: =VLOOKUP(A11,账簿!B:C,2,0) -> 002022 | Q11: =VLOOKUP(P11,账簿!A:B,2,0) -> 昌邑泓澄水业有限公司 | W11: =X11&AB11&AD11 -> 0020222026-04-215 | X11: =P11 -> 002022 | Y11: =X11 -> 002022 | Z11: =Q11 -> 昌邑泓澄水业有限公司 | AA11: =LEFT(B11,7) -> 2026-04 | AB11: =B11 -> 2026-04-21 | AC11: 记 | AD11: =VALUE(_xlfn.TEXTAFTER(C11,"-")) -> 5 | AE11: =D11 -> 对公贷款利息支付,中长期并购贷款利息收入 | AF11: 谭雅心 | AG11: 谭雅心 | AN11: =M11 -> 1002 | AP11: =D11 -> 对公贷款利息支付,中长期并购贷款利息收入 | AQ11: CNY | AR11: =F11 | AS11: =G11 -> 370500.01 | AT11: 01 | AU11: * | AV11: 1 | AW11: =AR11 | AX11: =AS11 -> 370500.01 | BQ11: =IF(N11="项目",VLOOKUP(O11,项目!B:C,2,0),IF(K11="空项目",VLOOKUP(K11,项目!B:C,2,0),"")) | BR11: =IFERROR(VLOOKUP(BQ11,项目!A:B,2,0),"") | BU11: =IF(N11="供应商",VLOOKUP(O11,供应商!B:C,2,0),"") | BV11: =IFERROR(VLOOKUP(BU11,供应商!A:B,2,0),"") | BW11: =IF(N11="客户",VLOOKUP(O11,客户!B:C,2,0),"") | BX11: =IFERROR(VLOOKUP(BW11,客户!A:B,2,0),"") | CU11: =IF(N11="费用项目",VLOOKUP(O11,费用项目!B:C,2,0),"") | CV11: =IFERROR(VLOOKUP(CU11,费用项目!A:B,2,0),"") | CW11: =IF(N11="银行账户",VLOOKUP(O11,银行变二级!B:C,2,0),"") -> 工商银行3066 | CX11: =IFERROR(VLOOKUP(O11,银行变二级!A:B,2,0),"") -> 工商银行3066
A12: 昌邑泓澄水业有限公司 | B12: 2026-04-21 | C12: 记-006 | D12: 跨行汇款手续费 | E12: 6603 财务费用-手续费 | F12: 314.28 | H12: =LEFT(E12,4) -> 6603 | I12: =IFERROR(LEFT(E12,FIND(" ",E12)-1),E12) -> 6603 | J12: =LEFT(MID(E12,FIND(" ",E12)+1,LEN(E12)),FIND("-",MID(E12,FIND(" ",E12)+1,LEN(E12))&"-")-1) -> 财务费用 | K12: =IFERROR(MID(MID(E12,FIND(" ",E12)+1,LEN(E12)),FIND("-",MID(E12,FIND(" ",E12)+1,LEN(E12)))+1,IFERROR(FIND("-",MID(E12,FIND(" ",E12)+1,LEN(E12)),FIND("-",MID(E12,FIND(" ",E12)+1,LEN(E12)))+1),LEN(MID(E12,FIND(" ",E12)+1,LEN(E12)))+1)-FIND("-",MID(E12,FIND(" ",E12)+1,LEN(E12)))-1),"") -> 手续费 | L12: =IFERROR(MID(MID(E12,FIND(" ",E12)+1,LEN(E12)),FIND("-",MID(E12,FIND(" ",E12)+1,LEN(E12)),FIND("-",MID(E12,FIND(" ",E12)+1,LEN(E12)))+1)+1,LEN(E12)),"") | M12: =IFERROR(IF(H12="1002",1002,VLOOKUP(I12,亿企科目!A:H,6,0)),VLOOKUP(H12,亿企科目!A:G,6,0)) -> 6603 | N12: =IFERROR(IF(H12="1002","银行账户",IF(H12="1123","供应商",VLOOKUP(I12,亿企科目!A:H,8,0))),"") -> 费用项目 | O12: =IF(N12=0,IF(M12="1002",K12,""),_xlfn.TEXTAFTER(E12,"-",-1)) -> 手续费 | P12: =VLOOKUP(A12,账簿!B:C,2,0) -> 002022 | Q12: =VLOOKUP(P12,账簿!A:B,2,0) -> 昌邑泓澄水业有限公司 | W12: =X12&AB12&AD12 -> 0020222026-04-216 | X12: =P12 -> 002022 | Y12: =X12 -> 002022 | Z12: =Q12 -> 昌邑泓澄水业有限公司 | AA12: =LEFT(B12,7) -> 2026-04 | AB12: =B12 -> 2026-04-21 | AC12: 记 | AD12: =VALUE(_xlfn.TEXTAFTER(C12,"-")) -> 6 | AE12: =D12 -> 跨行汇款手续费 | AF12: 谭雅心 | AG12: 谭雅心 | AN12: =M12 -> 6603 | AP12: =D12 -> 跨行汇款手续费 | AQ12: CNY | AR12: =F12 -> 314.28 | AS12: =G12 | AT12: 01 | AU12: * | AV12: 1 | AW12: =AR12 -> 314.28 | AX12: =AS12 | BQ12: =IF(N12="项目",VLOOKUP(O12,项目!B:C,2,0),IF(K12="空项目",VLOOKUP(K12,项目!B:C,2,0),"")) | BR12: =IFERROR(VLOOKUP(BQ12,项目!A:B,2,0),"") | BU12: =IF(N12="供应商",VLOOKUP(O12,供应商!B:C,2,0),"") | BV12: =IFERROR(VLOOKUP(BU12,供应商!A:B,2,0),"") | BW12: =IF(N12="客户",VLOOKUP(O12,客户!B:C,2,0),"") | BX12: =IFERROR(VLOOKUP(BW12,客户!A:B,2,0),"") | CU12: =IF(N12="费用项目",VLOOKUP(O12,费用项目!B:C,2,0),"") -> 660304 | CV12: =IFERROR(VLOOKUP(CU12,费用项目!A:B,2,0),"") -> 手续费 | CW12: =IF(N12="银行账户",VLOOKUP(O12,银行变二级!B:C,2,0),"") | CX12: =IFERROR(VLOOKUP(O12,银行变二级!A:B,2,0),"")
A13: 昌邑泓澄水业有限公司 | B13: 2026-04-21 | C13: 记-006 | D13: 跨行汇款手续费 | E13: 100201 银行存款-工商银行3066 | G13: 314.28 | H13: =LEFT(E13,4) -> 1002 | I13: =IFERROR(LEFT(E13,FIND(" ",E13)-1),E13) -> 100201 | J13: =LEFT(MID(E13,FIND(" ",E13)+1,LEN(E13)),FIND("-",MID(E13,FIND(" ",E13)+1,LEN(E13))&"-")-1) -> 银行存款 | K13: =IFERROR(MID(MID(E13,FIND(" ",E13)+1,LEN(E13)),FIND("-",MID(E13,FIND(" ",E13)+1,LEN(E13)))+1,IFERROR(FIND("-",MID(E13,FIND(" ",E13)+1,LEN(E13)),FIND("-",MID(E13,FIND(" ",E13)+1,LEN(E13)))+1),LEN(MID(E13,FIND(" ",E13)+1,LEN(E13)))+1)-FIND("-",MID(E13,FIND(" ",E13)+1,LEN(E13)))-1),"") -> 工商银行3066 | L13: =IFERROR(MID(MID(E13,FIND(" ",E13)+1,LEN(E13)),FIND("-",MID(E13,FIND(" ",E13)+1,LEN(E13)),FIND("-",MID(E13,FIND(" ",E13)+1,LEN(E13)))+1)+1,LEN(E13)),"") | M13: =IFERROR(IF(H13="1002",1002,VLOOKUP(I13,亿企科目!A:H,6,0)),VLOOKUP(H13,亿企科目!A:G,6,0)) -> 1002 | N13: =IFERROR(IF(H13="1002","银行账户",IF(H13="1123","供应商",VLOOKUP(I13,亿企科目!A:H,8,0))),"") -> 银行账户 | O13: =IF(N13=0,IF(M13="1002",K13,""),_xlfn.TEXTAFTER(E13,"-",-1)) -> 工商银行3066 | P13: =VLOOKUP(A13,账簿!B:C,2,0) -> 002022 | Q13: =VLOOKUP(P13,账簿!A:B,2,0) -> 昌邑泓澄水业有限公司 | W13: =X13&AB13&AD13 -> 0020222026-04-216 | X13: =P13 -> 002022 | Y13: =X13 -> 002022 | Z13: =Q13 -> 昌邑泓澄水业有限公司 | AA13: =LEFT(B13,7) -> 2026-04 | AB13: =B13 -> 2026-04-21 | AC13: 记 | AD13: =VALUE(_xlfn.TEXTAFTER(C13,"-")) -> 6 | AE13: =D13 -> 跨行汇款手续费 | AF13: 谭雅心 | AG13: 谭雅心 | AN13: =M13 -> 1002 | AP13: =D13 -> 跨行汇款手续费 | AQ13: CNY | AR13: =F13 | AS13: =G13 -> 314.28 | AT13: 01 | AU13: * | AV13: 1 | AW13: =AR13 | AX13: =AS13 -> 314.28 | BQ13: =IF(N13="项目",VLOOKUP(O13,项目!B:C,2,0),IF(K13="空项目",VLOOKUP(K13,项目!B:C,2,0),"")) | BR13: =IFERROR(VLOOKUP(BQ13,项目!A:B,2,0),"") | BU13: =IF(N13="供应商",VLOOKUP(O13,供应商!B:C,2,0),"") | BV13: =IFERROR(VLOOKUP(BU13,供应商!A:B,2,0),"") | BW13: =IF(N13="客户",VLOOKUP(O13,客户!B:C,2,0),"") | BX13: =IFERROR(VLOOKUP(BW13,客户!A:B,2,0),"") | CU13: =IF(N13="费用项目",VLOOKUP(O13,费用项目!B:C,2,0),"") | CV13: =IFERROR(VLOOKUP(CU13,费用项目!A:B,2,0),"") | CW13: =IF(N13="银行账户",VLOOKUP(O13,银行变二级!B:C,2,0),"") -> 工商银行3066 | CX13: =IFERROR(VLOOKUP(O13,银行变二级!A:B,2,0),"") -> 工商银行3066
A14: 昌邑泓澄水业有限公司 | B14: 2026-04-30 | C14: 记-007 | D14: 往来款,昌邑市城投股权投资管理有限公司 | E14: 122108 其他应收款-单位-昌邑市城投股权投资管理有限公司 | F14: 26000000 | H14: =LEFT(E14,4) -> 1221 | I14: =IFERROR(LEFT(E14,FIND(" ",E14)-1),E14) -> 122108 | J14: =LEFT(MID(E14,FIND(" ",E14)+1,LEN(E14)),FIND("-",MID(E14,FIND(" ",E14)+1,LEN(E14))&"-")-1) -> 其他应收款 | K14: =IFERROR(MID(MID(E14,FIND(" ",E14)+1,LEN(E14)),FIND("-",MID(E14,FIND(" ",E14)+1,LEN(E14)))+1,IFERROR(FIND("-",MID(E14,FIND(" ",E14)+1,LEN(E14)),FIND("-",MID(E14,FIND(" ",E14)+1,LEN(E14)))+1),LEN(MID(E14,FIND(" ",E14)+1,LEN(E14)))+1)-FIND("-",MID(E14,FIND(" ",E14)+1,LEN(E14)))-1),"") -> 单位 | L14: =IFERROR(MID(MID(E14,FIND(" ",E14)+1,LEN(E14)),FIND("-",MID(E14,FIND(" ",E14)+1,LEN(E14)),FIND("-",MID(E14,FIND(" ",E14)+1,LEN(E14)))+1)+1,LEN(E14)),"") -> 昌邑市城投股权投资管理有限公司 | M14: =IFERROR(IF(H14="1002",1002,VLOOKUP(I14,亿企科目!A:H,6,0)),VLOOKUP(H14,亿企科目!A:G,6,0)) -> 122102 | N14: =IFERROR(IF(H14="1002","银行账户",IF(H14="1123","供应商",VLOOKUP(I14,亿企科目!A:H,8,0))),"") -> 客户 | O14: =IF(N14=0,IF(M14="1002",K14,""),_xlfn.TEXTAFTER(E14,"-",-1)) -> 昌邑市城投股权投资管理有限公司 | P14: =VLOOKUP(A14,账簿!B:C,2,0) -> 002022 | Q14: =VLOOKUP(P14,账簿!A:B,2,0) -> 昌邑泓澄水业有限公司 | W14: =X14&AB14&AD14 -> 0020222026-04-307 | X14: =P14 -> 002022 | Y14: =X14 -> 002022 | Z14: =Q14 -> 昌邑泓澄水业有限公司 | AA14: =LEFT(B14,7) -> 2026-04 | AB14: =B14 -> 2026-04-30 | AC14: 记 | AD14: =VALUE(_xlfn.TEXTAFTER(C14,"-")) -> 7 | AE14: =D14 -> 往来款,昌邑市城投股权投资管理有限公司 | AF14: 谭雅心 | AG14: 谭雅心 | AN14: =M14 -> 122102 | AP14: =D14 -> 往来款,昌邑市城投股权投资管理有限公司 | AQ14: CNY | AR14: =F14 -> 26000000 | AS14: =G14 | AT14: 01 | AU14: * | AV14: 1 | AW14: =AR14 -> 26000000 | AX14: =AS14 | BQ14: =IF(N14="项目",VLOOKUP(O14,项目!B:C,2,0),IF(K14="空项目",VLOOKUP(K14,项目!B:C,2,0),"")) | BR14: =IFERROR(VLOOKUP(BQ14,项目!A:B,2,0),"") | BU14: =IF(N14="供应商",VLOOKUP(O14,供应商!B:C,2,0),"") | BV14: =IFERROR(VLOOKUP(BU14,供应商!A:B,2,0),"") | BW14: =IF(N14="客户",VLOOKUP(O14,客户!B:C,2,0),"") -> 002008 | BX14: =IFERROR(VLOOKUP(BW14,客户!A:B,2,0),"") -> 昌邑市城投股权投资管理有限公司 | CU14: =IF(N14="费用项目",VLOOKUP(O14,费用项目!B:C,2,0),"") | CV14: =IFERROR(VLOOKUP(CU14,费用项目!A:B,2,0),"") | CW14: =IF(N14="银行账户",VLOOKUP(O14,银行变二级!B:C,2,0),"") | CX14: =IFERROR(VLOOKUP(O14,银行变二级!A:B,2,0),"")
A15: 昌邑泓澄水业有限公司 | B15: 2026-04-30 | C15: 记-007 | D15: 往来款,昌邑市城投股权投资管理有限公司 | E15: 100201 银行存款-工商银行3066 | G15: 26000000 | H15: =LEFT(E15,4) -> 1002 | I15: =IFERROR(LEFT(E15,FIND(" ",E15)-1),E15) -> 100201 | J15: =LEFT(MID(E15,FIND(" ",E15)+1,LEN(E15)),FIND("-",MID(E15,FIND(" ",E15)+1,LEN(E15))&"-")-1) -> 银行存款 | K15: =IFERROR(MID(MID(E15,FIND(" ",E15)+1,LEN(E15)),FIND("-",MID(E15,FIND(" ",E15)+1,LEN(E15)))+1,IFERROR(FIND("-",MID(E15,FIND(" ",E15)+1,LEN(E15)),FIND("-",MID(E15,FIND(" ",E15)+1,LEN(E15)))+1),LEN(MID(E15,FIND(" ",E15)+1,LEN(E15)))+1)-FIND("-",MID(E15,FIND(" ",E15)+1,LEN(E15)))-1),"") -> 工商银行3066 | L15: =IFERROR(MID(MID(E15,FIND(" ",E15)+1,LEN(E15)),FIND("-",MID(E15,FIND(" ",E15)+1,LEN(E15)),FIND("-",MID(E15,FIND(" ",E15)+1,LEN(E15)))+1)+1,LEN(E15)),"") | M15: =IFERROR(IF(H15="1002",1002,VLOOKUP(I15,亿企科目!A:H,6,0)),VLOOKUP(H15,亿企科目!A:G,6,0)) -> 1002 | N15: =IFERROR(IF(H15="1002","银行账户",IF(H15="1123","供应商",VLOOKUP(I15,亿企科目!A:H,8,0))),"") -> 银行账户 | O15: =IF(N15=0,IF(M15="1002",K15,""),_xlfn.TEXTAFTER(E15,"-",-1)) -> 工商银行3066 | P15: =VLOOKUP(A15,账簿!B:C,2,0) -> 002022 | Q15: =VLOOKUP(P15,账簿!A:B,2,0) -> 昌邑泓澄水业有限公司 | W15: =X15&AB15&AD15 -> 0020222026-04-307 | X15: =P15 -> 002022 | Y15: =X15 -> 002022 | Z15: =Q15 -> 昌邑泓澄水业有限公司 | AA15: =LEFT(B15,7) -> 2026-04 | AB15: =B15 -> 2026-04-30 | AC15: 记 | AD15: =VALUE(_xlfn.TEXTAFTER(C15,"-")) -> 7 | AE15: =D15 -> 往来款,昌邑市城投股权投资管理有限公司 | AF15: 谭雅心 | AG15: 谭雅心 | AN15: =M15 -> 1002 | AP15: =D15 -> 往来款,昌邑市城投股权投资管理有限公司 | AQ15: CNY | AR15: =F15 | AS15: =G15 -> 26000000 | AT15: 01 | AU15: * | AV15: 1 | AW15: =AR15 | AX15: =AS15 -> 26000000 | BQ15: =IF(N15="项目",VLOOKUP(O15,项目!B:C,2,0),IF(K15="空项目",VLOOKUP(K15,项目!B:C,2,0),"")) | BR15: =IFERROR(VLOOKUP(BQ15,项目!A:B,2,0),"") | BU15: =IF(N15="供应商",VLOOKUP(O15,供应商!B:C,2,0),"") | BV15: =IFERROR(VLOOKUP(BU15,供应商!A:B,2,0),"") | BW15: =IF(N15="客户",VLOOKUP(O15,客户!B:C,2,0),"") | BX15: =IFERROR(VLOOKUP(BW15,客户!A:B,2,0),"") | CU15: =IF(N15="费用项目",VLOOKUP(O15,费用项目!B:C,2,0),"") | CV15: =IFERROR(VLOOKUP(CU15,费用项目!A:B,2,0),"") | CW15: =IF(N15="银行账户",VLOOKUP(O15,银行变二级!B:C,2,0),"") -> 工商银行3066 | CX15: =IFERROR(VLOOKUP(O15,银行变二级!A:B,2,0),"") -> 工商银行3066
A16: 昌邑泓澄水业有限公司 | B16: 2026-04-30 | C16: 记-008 | D16: 结转本月损益 | E16: 4103 本年利润 | F16: 370814.29 | H16: =LEFT(E16,4) -> 4103 | I16: =IFERROR(LEFT(E16,FIND(" ",E16)-1),E16) -> 4103 | J16: =LEFT(MID(E16,FIND(" ",E16)+1,LEN(E16)),FIND("-",MID(E16,FIND(" ",E16)+1,LEN(E16))&"-")-1) -> 本年利润 | K16: =IFERROR(MID(MID(E16,FIND(" ",E16)+1,LEN(E16)),FIND("-",MID(E16,FIND(" ",E16)+1,LEN(E16)))+1,IFERROR(FIND("-",MID(E16,FIND(" ",E16)+1,LEN(E16)),FIND("-",MID(E16,FIND(" ",E16)+1,LEN(E16)))+1),LEN(MID(E16,FIND(" ",E16)+1,LEN(E16)))+1)-FIND("-",MID(E16,FIND(" ",E16)+1,LEN(E16)))-1),"") | L16: =IFERROR(MID(MID(E16,FIND(" ",E16)+1,LEN(E16)),FIND("-",MID(E16,FIND(" ",E16)+1,LEN(E16)),FIND("-",MID(E16,FIND(" ",E16)+1,LEN(E16)))+1)+1,LEN(E16)),"") | M16: =IFERROR(IF(H16="1002",1002,VLOOKUP(I16,亿企科目!A:H,6,0)),VLOOKUP(H16,亿企科目!A:G,6,0)) -> 4103 | N16: =IFERROR(IF(H16="1002","银行账户",IF(H16="1123","供应商",VLOOKUP(I16,亿企科目!A:H,8,0))),"") -> 0 | O16: =IF(N16=0,IF(M16="1002",K16,""),_xlfn.TEXTAFTER(E16,"-",-1)) | P16: =VLOOKUP(A16,账簿!B:C,2,0) -> 002022 | Q16: =VLOOKUP(P16,账簿!A:B,2,0) -> 昌邑泓澄水业有限公司 | W16: =X16&AB16&AD16 -> 0020222026-04-308 | X16: =P16 -> 002022 | Y16: =X16 -> 002022 | Z16: =Q16 -> 昌邑泓澄水业有限公司 | AA16: =LEFT(B16,7) -> 2026-04 | AB16: =B16 -> 2026-04-30 | AC16: 记 | AD16: =VALUE(_xlfn.TEXTAFTER(C16,"-")) -> 8 | AE16: =D16 -> 结转本月损益 | AF16: 谭雅心 | AG16: 谭雅心 | AN16: =M16 -> 4103 | AP16: =D16 -> 结转本月损益 | AQ16: CNY | AR16: =F16 -> 370814.29 | AS16: =G16 | AT16: 01 | AU16: * | AV16: 1 | AW16: =AR16 -> 370814.29 | AX16: =AS16 | BQ16: =IF(N16="项目",VLOOKUP(O16,项目!B:C,2,0),IF(K16="空项目",VLOOKUP(K16,项目!B:C,2,0),"")) | BR16: =IFERROR(VLOOKUP(BQ16,项目!A:B,2,0),"") | BU16: =IF(N16="供应商",VLOOKUP(O16,供应商!B:C,2,0),"") | BV16: =IFERROR(VLOOKUP(BU16,供应商!A:B,2,0),"") | BW16: =IF(N16="客户",VLOOKUP(O16,客户!B:C,2,0),"") | BX16: =IFERROR(VLOOKUP(BW16,客户!A:B,2,0),"") | CU16: =IF(N16="费用项目",VLOOKUP(O16,费用项目!B:C,2,0),"") | CV16: =IFERROR(VLOOKUP(CU16,费用项目!A:B,2,0),"") | CW16: =IF(N16="银行账户",VLOOKUP(O16,银行变二级!B:C,2,0),"") | CX16: =IFERROR(VLOOKUP(O16,银行变二级!A:B,2,0),"")
A17: 昌邑泓澄水业有限公司 | B17: 2026-04-30 | C17: 记-008 | D17: 结转本月损益 | E17: 6603 财务费用-利息支出 | G17: 370500.01 | H17: =LEFT(E17,4) -> 6603 | I17: =IFERROR(LEFT(E17,FIND(" ",E17)-1),E17) -> 6603 | J17: =LEFT(MID(E17,FIND(" ",E17)+1,LEN(E17)),FIND("-",MID(E17,FIND(" ",E17)+1,LEN(E17))&"-")-1) -> 财务费用 | K17: =IFERROR(MID(MID(E17,FIND(" ",E17)+1,LEN(E17)),FIND("-",MID(E17,FIND(" ",E17)+1,LEN(E17)))+1,IFERROR(FIND("-",MID(E17,FIND(" ",E17)+1,LEN(E17)),FIND("-",MID(E17,FIND(" ",E17)+1,LEN(E17)))+1),LEN(MID(E17,FIND(" ",E17)+1,LEN(E17)))+1)-FIND("-",MID(E17,FIND(" ",E17)+1,LEN(E17)))-1),"") -> 利息支出 | L17: =IFERROR(MID(MID(E17,FIND(" ",E17)+1,LEN(E17)),FIND("-",MID(E17,FIND(" ",E17)+1,LEN(E17)),FIND("-",MID(E17,FIND(" ",E17)+1,LEN(E17)))+1)+1,LEN(E17)),"") | M17: =IFERROR(IF(H17="1002",1002,VLOOKUP(I17,亿企科目!A:H,6,0)),VLOOKUP(H17,亿企科目!A:G,6,0)) -> 6603 | N17: =IFERROR(IF(H17="1002","银行账户",IF(H17="1123","供应商",VLOOKUP(I17,亿企科目!A:H,8,0))),"") -> 费用项目 | O17: =IF(N17=0,IF(M17="1002",K17,""),_xlfn.TEXTAFTER(E17,"-",-1)) -> 利息支出 | P17: =VLOOKUP(A17,账簿!B:C,2,0) -> 002022 | Q17: =VLOOKUP(P17,账簿!A:B,2,0) -> 昌邑泓澄水业有限公司 | W17: =X17&AB17&AD17 -> 0020222026-04-308 | X17: =P17 -> 002022 | Y17: =X17 -> 002022 | Z17: =Q17 -> 昌邑泓澄水业有限公司 | AA17: =LEFT(B17,7) -> 2026-04 | AB17: =B17 -> 2026-04-30 | AC17: 记 | AD17: =VALUE(_xlfn.TEXTAFTER(C17,"-")) -> 8 | AE17: =D17 -> 结转本月损益 | AF17: 谭雅心 | AG17: 谭雅心 | AN17: =M17 -> 6603 | AP17: =D17 -> 结转本月损益 | AQ17: CNY | AR17: =F17 | AS17: =G17 -> 370500.01 | AT17: 01 | AU17: * | AV17: 1 | AW17: =AR17 | AX17: =AS17 -> 370500.01 | BQ17: =IF(N17="项目",VLOOKUP(O17,项目!B:C,2,0),IF(K17="空项目",VLOOKUP(K17,项目!B:C,2,0),"")) | BR17: =IFERROR(VLOOKUP(BQ17,项目!A:B,2,0),"") | BU17: =IF(N17="供应商",VLOOKUP(O17,供应商!B:C,2,0),"") | BV17: =IFERROR(VLOOKUP(BU17,供应商!A:B,2,0),"") | BW17: =IF(N17="客户",VLOOKUP(O17,客户!B:C,2,0),"") | BX17: =IFERROR(VLOOKUP(BW17,客户!A:B,2,0),"") | CU17: =IF(N17="费用项目",VLOOKUP(O17,费用项目!B:C,2,0),"") -> 660302 | CV17: =IFERROR(VLOOKUP(CU17,费用项目!A:B,2,0),"") -> 利息支出 | CW17: =IF(N17="银行账户",VLOOKUP(O17,银行变二级!B:C,2,0),"") | CX17: =IFERROR(VLOOKUP(O17,银行变二级!A:B,2,0),"")
A18: 昌邑泓澄水业有限公司 | B18: 2026-04-30 | C18: 记-008 | D18: 结转本月损益 | E18: 6603 财务费用-手续费 | G18: 314.28 | H18: =LEFT(E18,4) -> 6603 | I18: =IFERROR(LEFT(E18,FIND(" ",E18)-1),E18) -> 6603 | J18: =LEFT(MID(E18,FIND(" ",E18)+1,LEN(E18)),FIND("-",MID(E18,FIND(" ",E18)+1,LEN(E18))&"-")-1) -> 财务费用 | K18: =IFERROR(MID(MID(E18,FIND(" ",E18)+1,LEN(E18)),FIND("-",MID(E18,FIND(" ",E18)+1,LEN(E18)))+1,IFERROR(FIND("-",MID(E18,FIND(" ",E18)+1,LEN(E18)),FIND("-",MID(E18,FIND(" ",E18)+1,LEN(E18)))+1),LEN(MID(E18,FIND(" ",E18)+1,LEN(E18)))+1)-FIND("-",MID(E18,FIND(" ",E18)+1,LEN(E18)))-1),"") -> 手续费 | L18: =IFERROR(MID(MID(E18,FIND(" ",E18)+1,LEN(E18)),FIND("-",MID(E18,FIND(" ",E18)+1,LEN(E18)),FIND("-",MID(E18,FIND(" ",E18)+1,LEN(E18)))+1)+1,LEN(E18)),"") | M18: =IFERROR(IF(H18="1002",1002,VLOOKUP(I18,亿企科目!A:H,6,0)),VLOOKUP(H18,亿企科目!A:G,6,0)) -> 6603 | N18: =IFERROR(IF(H18="1002","银行账户",IF(H18="1123","供应商",VLOOKUP(I18,亿企科目!A:H,8,0))),"") -> 费用项目 | O18: =IF(N18=0,IF(M18="1002",K18,""),_xlfn.TEXTAFTER(E18,"-",-1)) -> 手续费 | P18: =VLOOKUP(A18,账簿!B:C,2,0) -> 002022 | Q18: =VLOOKUP(P18,账簿!A:B,2,0) -> 昌邑泓澄水业有限公司 | W18: =X18&AB18&AD18 -> 0020222026-04-308 | X18: =P18 -> 002022 | Y18: =X18 -> 002022 | Z18: =Q18 -> 昌邑泓澄水业有限公司 | AA18: =LEFT(B18,7) -> 2026-04 | AB18: =B18 -> 2026-04-30 | AC18: 记 | AD18: =VALUE(_xlfn.TEXTAFTER(C18,"-")) -> 8 | AE18: =D18 -> 结转本月损益 | AF18: 谭雅心 | AG18: 谭雅心 | AN18: =M18 -> 6603 | AP18: =D18 -> 结转本月损益 | AQ18: CNY | AR18: =F18 | AS18: =G18 -> 314.28 | AT18: 01 | AU18: * | AV18: 1 | AW18: =AR18 | AX18: =AS18 -> 314.28 | BQ18: =IF(N18="项目",VLOOKUP(O18,项目!B:C,2,0),IF(K18="空项目",VLOOKUP(K18,项目!B:C,2,0),"")) | BR18: =IFERROR(VLOOKUP(BQ18,项目!A:B,2,0),"") | BU18: =IF(N18="供应商",VLOOKUP(O18,供应商!B:C,2,0),"") | BV18: =IFERROR(VLOOKUP(BU18,供应商!A:B,2,0),"") | BW18: =IF(N18="客户",VLOOKUP(O18,客户!B:C,2,0),"") | BX18: =IFERROR(VLOOKUP(BW18,客户!A:B,2,0),"") | CU18: =IF(N18="费用项目",VLOOKUP(O18,费用项目!B:C,2,0),"") -> 660304 | CV18: =IFERROR(VLOOKUP(CU18,费用项目!A:B,2,0),"") -> 手续费 | CW18: =IF(N18="银行账户",VLOOKUP(O18,银行变二级!B:C,2,0),"") | CX18: =IFERROR(VLOOKUP(O18,银行变二级!A:B,2,0),"")
A19: 昌邑市昌荣城乡建设有限公司 | B19: 2026-04-21 | C19: 记-001 | D19: 2026-04-21,昌邑市昌荣城乡建设有限公司,贷款还款 | E19: 6603 财务费用-利息支出 | F19: 13431.07 | H19: =LEFT(E19,4) -> 6603 | I19: =IFERROR(LEFT(E19,FIND(" ",E19)-1),E19) -> 6603 | J19: =LEFT(MID(E19,FIND(" ",E19)+1,LEN(E19)),FIND("-",MID(E19,FIND(" ",E19)+1,LEN(E19))&"-")-1) -> 财务费用 | K19: =IFERROR(MID(MID(E19,FIND(" ",E19)+1,LEN(E19)),FIND("-",MID(E19,FIND(" ",E19)+1,LEN(E19)))+1,IFERROR(FIND("-",MID(E19,FIND(" ",E19)+1,LEN(E19)),FIND("-",MID(E19,FIND(" ",E19)+1,LEN(E19)))+1),LEN(MID(E19,FIND(" ",E19)+1,LEN(E19)))+1)-FIND("-",MID(E19,FIND(" ",E19)+1,LEN(E19)))-1),"") -> 利息支出 | L19: =IFERROR(MID(MID(E19,FIND(" ",E19)+1,LEN(E19)),FIND("-",MID(E19,FIND(" ",E19)+1,LEN(E19)),FIND("-",MID(E19,FIND(" ",E19)+1,LEN(E19)))+1)+1,LEN(E19)),"") | M19: =IFERROR(IF(H19="1002",1002,VLOOKUP(I19,亿企科目!A:H,6,0)),VLOOKUP(H19,亿企科目!A:G,6,0)) -> 6603 | N19: =IFERROR(IF(H19="1002","银行账户",IF(H19="1123","供应商",VLOOKUP(I19,亿企科目!A:H,8,0))),"") -> 费用项目 | O19: =IF(N19=0,IF(M19="1002",K19,""),_xlfn.TEXTAFTER(E19,"-",-1)) -> 利息支出 | P19: =VLOOKUP(A19,账簿!B:C,2,0) -> 003012 | Q19: =VLOOKUP(P19,账簿!A:B,2,0) -> 昌邑市昌荣城乡建设有限公司 | W19: =X19&AB19&AD19 -> 0030122026-04-211 | X19: =P19 -> 003012 | Y19: =X19 -> 003012 | Z19: =Q19 -> 昌邑市昌荣城乡建设有限公司 | AA19: =LEFT(B19,7) -> 2026-04 | AB19: =B19 -> 2026-04-21 | AC19: 记 | AD19: =VALUE(_xlfn.TEXTAFTER(C19,"-")) -> 1 | AE19: =D19 -> 2026-04-21,昌邑市昌荣城乡建设有限公司,贷款还款 | AF19: 谭雅心 | AG19: 谭雅心 | AN19: =M19 -> 6603 | AP19: =D19 -> 2026-04-21,昌邑市昌荣城乡建设有限公司,贷款还款 | AQ19: CNY | AR19: =F19 -> 13431.07 | AS19: =G19 | AT19: 01 | AU19: * | AV19: 1 | AW19: =AR19 -> 13431.07 | AX19: =AS19 | BQ19: =IF(N19="项目",VLOOKUP(O19,项目!B:C,2,0),IF(K19="空项目",VLOOKUP(K19,项目!B:C,2,0),"")) | BR19: =IFERROR(VLOOKUP(BQ19,项目!A:B,2,0),"") | BU19: =IF(N19="供应商",VLOOKUP(O19,供应商!B:C,2,0),"") | BV19: =IFERROR(VLOOKUP(BU19,供应商!A:B,2,0),"") | BW19: =IF(N19="客户",VLOOKUP(O19,客户!B:C,2,0),"") | BX19: =IFERROR(VLOOKUP(BW19,客户!A:B,2,0),"") | CU19: =IF(N19="费用项目",VLOOKUP(O19,费用项目!B:C,2,0),"") -> 660302 | CV19: =IFERROR(VLOOKUP(CU19,费用项目!A:B,2,0),"") -> 利息支出 | CW19: =IF(N19="银行账户",VLOOKUP(O19,银行变二级!B:C,2,0),"") | CX19: =IFERROR(VLOOKUP(O19,银行变二级!A:B,2,0),"")
A20: 昌邑市昌荣城乡建设有限公司 | B20: 2026-04-21 | C20: 记-001 | D20: 2026-04-21,昌邑市昌荣城乡建设有限公司,贷款还款 | E20: 100203 银行存款-潍坊银行5103 | G20: 13431.07 | H20: =LEFT(E20,4) -> 1002 | I20: =IFERROR(LEFT(E20,FIND(" ",E20)-1),E20) -> 100203 | J20: =LEFT(MID(E20,FIND(" ",E20)+1,LEN(E20)),FIND("-",MID(E20,FIND(" ",E20)+1,LEN(E20))&"-")-1) -> 银行存款 | K20: =IFERROR(MID(MID(E20,FIND(" ",E20)+1,LEN(E20)),FIND("-",MID(E20,FIND(" ",E20)+1,LEN(E20)))+1,IFERROR(FIND("-",MID(E20,FIND(" ",E20)+1,LEN(E20)),FIND("-",MID(E20,FIND(" ",E20)+1,LEN(E20)))+1),LEN(MID(E20,FIND(" ",E20)+1,LEN(E20)))+1)-FIND("-",MID(E20,FIND(" ",E20)+1,LEN(E20)))-1),"") -> 潍坊银行5103 | L20: =IFERROR(MID(MID(E20,FIND(" ",E20)+1,LEN(E20)),FIND("-",MID(E20,FIND(" ",E20)+1,LEN(E20)),FIND("-",MID(E20,FIND(" ",E20)+1,LEN(E20)))+1)+1,LEN(E20)),"") | M20: =IFERROR(IF(H20="1002",1002,VLOOKUP(I20,亿企科目!A:H,6,0)),VLOOKUP(H20,亿企科目!A:G,6,0)) -> 1002 | N20: =IFERROR(IF(H20="1002","银行账户",IF(H20="1123","供应商",VLOOKUP(I20,亿企科目!A:H,8,0))),"") -> 银行账户 | O20: =IF(N20=0,IF(M20="1002",K20,""),_xlfn.TEXTAFTER(E20,"-",-1)) -> 潍坊银行5103 | P20: =VLOOKUP(A20,账簿!B:C,2,0) -> 003012 | Q20: =VLOOKUP(P20,账簿!A:B,2,0) -> 昌邑市昌荣城乡建设有限公司 | W20: =X20&AB20&AD20 -> 0030122026-04-211 | X20: =P20 -> 003012 | Y20: =X20 -> 003012 | Z20: =Q20 -> 昌邑市昌荣城乡建设有限公司 | AA20: =LEFT(B20,7) -> 2026-04 | AB20: =B20 -> 2026-04-21 | AC20: 记 | AD20: =VALUE(_xlfn.TEXTAFTER(C20,"-")) -> 1 | AE20: =D20 -> 2026-04-21,昌邑市昌荣城乡建设有限公司,贷款还款 | AF20: 谭雅心 | AG20: 谭雅心 | AN20: =M20 -> 1002 | AP20: =D20 -> 2026-04-21,昌邑市昌荣城乡建设有限公司,贷款还款 | AQ20: CNY | AR20: =F20 | AS20: =G20 -> 13431.07 | AT20: 01 | AU20: * | AV20: 1 | AW20: =AR20 | AX20: =AS20 -> 13431.07 | BQ20: =IF(N20="项目",VLOOKUP(O20,项目!B:C,2,0),IF(K20="空项目",VLOOKUP(K20,项目!B:C,2,0),"")) | BR20: =IFERROR(VLOOKUP(BQ20,项目!A:B,2,0),"") | BU20: =IF(N20="供应商",VLOOKUP(O20,供应商!B:C,2,0),"") | BV20: =IFERROR(VLOOKUP(BU20,供应商!A:B,2,0),"") | BW20: =IF(N20="客户",VLOOKUP(O20,客户!B:C,2,0),"") | BX20: =IFERROR(VLOOKUP(BW20,客户!A:B,2,0),"") | CU20: =IF(N20="费用项目",VLOOKUP(O20,费用项目!B:C,2,0),"") | CV20: =IFERROR(VLOOKUP(CU20,费用项目!A:B,2,0),"") | CW20: =IF(N20="银行账户",VLOOKUP(O20,银行变二级!B:C,2,0),"") -> 潍坊银行5103 | CX20: =IFERROR(VLOOKUP(O20,银行变二级!A:B,2,0),"") -> 潍坊银行5103
A21: 昌邑市昌荣城乡建设有限公司 | B21: 2026-04-21 | C21: 记-002 | D21: 2026-04-21,昌邑市国有资产经营投资有限公司,往来款 | E21: 100203 银行存款-潍坊银行5103 | F21: 180000 | H21: =LEFT(E21,4) -> 1002 | I21: =IFERROR(LEFT(E21,FIND(" ",E21)-1),E21) -> 100203 | J21: =LEFT(MID(E21,FIND(" ",E21)+1,LEN(E21)),FIND("-",MID(E21,FIND(" ",E21)+1,LEN(E21))&"-")-1) -> 银行存款 | K21: =IFERROR(MID(MID(E21,FIND(" ",E21)+1,LEN(E21)),FIND("-",MID(E21,FIND(" ",E21)+1,LEN(E21)))+1,IFERROR(FIND("-",MID(E21,FIND(" ",E21)+1,LEN(E21)),FIND("-",MID(E21,FIND(" ",E21)+1,LEN(E21)))+1),LEN(MID(E21,FIND(" ",E21)+1,LEN(E21)))+1)-FIND("-",MID(E21,FIND(" ",E21)+1,LEN(E21)))-1),"") -> 潍坊银行5103 | L21: =IFERROR(MID(MID(E21,FIND(" ",E21)+1,LEN(E21)),FIND("-",MID(E21,FIND(" ",E21)+1,LEN(E21)),FIND("-",MID(E21,FIND(" ",E21)+1,LEN(E21)))+1)+1,LEN(E21)),"") | M21: =IFERROR(IF(H21="1002",1002,VLOOKUP(I21,亿企科目!A:H,6,0)),VLOOKUP(H21,亿企科目!A:G,6,0)) -> 1002 | N21: =IFERROR(IF(H21="1002","银行账户",IF(H21="1123","供应商",VLOOKUP(I21,亿企科目!A:H,8,0))),"") -> 银行账户 | O21: =IF(N21=0,IF(M21="1002",K21,""),_xlfn.TEXTAFTER(E21,"-",-1)) -> 潍坊银行5103 | P21: =VLOOKUP(A21,账簿!B:C,2,0) -> 003012 | Q21: =VLOOKUP(P21,账簿!A:B,2,0) -> 昌邑市昌荣城乡建设有限公司 | W21: =X21&AB21&AD21 -> 0030122026-04-212 | X21: =P21 -> 003012 | Y21: =X21 -> 003012 | Z21: =Q21 -> 昌邑市昌荣城乡建设有限公司 | AA21: =LEFT(B21,7) -> 2026-04 | AB21: =B21 -> 2026-04-21 | AC21: 记 | AD21: =VALUE(_xlfn.TEXTAFTER(C21,"-")) -> 2 | AE21: =D21 -> 2026-04-21,昌邑市国有资产经营投资有限公司,往来款 | AF21: 谭雅心 | AG21: 谭雅心 | AN21: =M21 -> 1002 | AP21: =D21 -> 2026-04-21,昌邑市国有资产经营投资有限公司,往来款 | AQ21: CNY | AR21: =F21 -> 180000 | AS21: =G21 | AT21: 01 | AU21: * | AV21: 1 | AW21: =AR21 -> 180000 | AX21: =AS21 | BQ21: =IF(N21="项目",VLOOKUP(O21,项目!B:C,2,0),IF(K21="空项目",VLOOKUP(K21,项目!B:C,2,0),"")) | BR21: =IFERROR(VLOOKUP(BQ21,项目!A:B,2,0),"") | BU21: =IF(N21="供应商",VLOOKUP(O21,供应商!B:C,2,0),"") | BV21: =IFERROR(VLOOKUP(BU21,供应商!A:B,2,0),"") | BW21: =IF(N21="客户",VLOOKUP(O21,客户!B:C,2,0),"") | BX21: =IFERROR(VLOOKUP(BW21,客户!A:B,2,0),"") | CU21: =IF(N21="费用项目",VLOOKUP(O21,费用项目!B:C,2,0),"") | CV21: =IFERROR(VLOOKUP(CU21,费用项目!A:B,2,0),"") | CW21: =IF(N21="银行账户",VLOOKUP(O21,银行变二级!B:C,2,0),"") -> 潍坊银行5103 | CX21: =IFERROR(VLOOKUP(O21,银行变二级!A:B,2,0),"") -> 潍坊银行5103
A22: 昌邑市昌荣城乡建设有限公司 | B22: 2026-04-21 | C22: 记-002 | D22: 2026-04-21,昌邑市国有资产经营投资有限公司,往来款 | E22: 122108 其他应收款-单位-昌邑市国有资产经营投资有限公司 | G22: 180000 | H22: =LEFT(E22,4) -> 1221 | I22: =IFERROR(LEFT(E22,FIND(" ",E22)-1),E22) -> 122108 | J22: =LEFT(MID(E22,FIND(" ",E22)+1,LEN(E22)),FIND("-",MID(E22,FIND(" ",E22)+1,LEN(E22))&"-")-1) -> 其他应收款 | K22: =IFERROR(MID(MID(E22,FIND(" ",E22)+1,LEN(E22)),FIND("-",MID(E22,FIND(" ",E22)+1,LEN(E22)))+1,IFERROR(FIND("-",MID(E22,FIND(" ",E22)+1,LEN(E22)),FIND("-",MID(E22,FIND(" ",E22)+1,LEN(E22)))+1),LEN(MID(E22,FIND(" ",E22)+1,LEN(E22)))+1)-FIND("-",MID(E22,FIND(" ",E22)+1,LEN(E22)))-1),"") -> 单位 | L22: =IFERROR(MID(MID(E22,FIND(" ",E22)+1,LEN(E22)),FIND("-",MID(E22,FIND(" ",E22)+1,LEN(E22)),FIND("-",MID(E22,FIND(" ",E22)+1,LEN(E22)))+1)+1,LEN(E22)),"") -> 昌邑市国有资产经营投资有限公司 | M22: =IFERROR(IF(H22="1002",1002,VLOOKUP(I22,亿企科目!A:H,6,0)),VLOOKUP(H22,亿企科目!A:G,6,0)) -> 122102 | N22: =IFERROR(IF(H22="1002","银行账户",IF(H22="1123","供应商",VLOOKUP(I22,亿企科目!A:H,8,0))),"") -> 客户 | O22: =IF(N22=0,IF(M22="1002",K22,""),_xlfn.TEXTAFTER(E22,"-",-1)) -> 昌邑市国有资产经营投资有限公司 | P22: =VLOOKUP(A22,账簿!B:C,2,0) -> 003012 | Q22: =VLOOKUP(P22,账簿!A:B,2,0) -> 昌邑市昌荣城乡建设有限公司 | W22: =X22&AB22&AD22 -> 0030122026-04-212 | X22: =P22 -> 003012 | Y22: =X22 -> 003012 | Z22: =Q22 -> 昌邑市昌荣城乡建设有限公司 | AA22: =LEFT(B22,7) -> 2026-04 | AB22: =B22 -> 2026-04-21 | AC22: 记 | AD22: =VALUE(_xlfn.TEXTAFTER(C22,"-")) -> 2 | AE22: =D22 -> 2026-04-21,昌邑市国有资产经营投资有限公司,往来款 | AF22: 谭雅心 | AG22: 谭雅心 | AN22: =M22 -> 122102 | AP22: =D22 -> 2026-04-21,昌邑市国有资产经营投资有限公司,往来款 | AQ22: CNY | AR22: =F22 | AS22: =G22 -> 180000 | AT22: 01 | AU22: * | AV22: 1 | AW22: =AR22 | AX22: =AS22 -> 180000 | BQ22: =IF(N22="项目",VLOOKUP(O22,项目!B:C,2,0),IF(K22="空项目",VLOOKUP(K22,项目!B:C,2,0),"")) | BR22: =IFERROR(VLOOKUP(BQ22,项目!A:B,2,0),"") | BU22: =IF(N22="供应商",VLOOKUP(O22,供应商!B:C,2,0),"") | BV22: =IFERROR(VLOOKUP(BU22,供应商!A:B,2,0),"") | BW22: =IF(N22="客户",VLOOKUP(O22,客户!B:C,2,0),"") -> 003 | BX22: =IFERROR(VLOOKUP(BW22,客户!A:B,2,0),"") -> 昌邑市国有资产经营投资有限公司 | CU22: =IF(N22="费用项目",VLOOKUP(O22,费用项目!B:C,2,0),"") | CV22: =IFERROR(VLOOKUP(CU22,费用项目!A:B,2,0),"") | CW22: =IF(N22="银行账户",VLOOKUP(O22,银行变二级!B:C,2,0),"") | CX22: =IFERROR(VLOOKUP(O22,银行变二级!A:B,2,0),"")
A23: 昌邑市昌荣城乡建设有限公司 | B23: 2026-04-21 | C23: 记-003 | D23: 2026-04-21,昌邑市昌荣城乡建设有限公司,贷款还款 | E23: 6603 财务费用-利息支出 | F23: 133818.93 | H23: =LEFT(E23,4) -> 6603 | I23: =IFERROR(LEFT(E23,FIND(" ",E23)-1),E23) -> 6603 | J23: =LEFT(MID(E23,FIND(" ",E23)+1,LEN(E23)),FIND("-",MID(E23,FIND(" ",E23)+1,LEN(E23))&"-")-1) -> 财务费用 | K23: =IFERROR(MID(MID(E23,FIND(" ",E23)+1,LEN(E23)),FIND("-",MID(E23,FIND(" ",E23)+1,LEN(E23)))+1,IFERROR(FIND("-",MID(E23,FIND(" ",E23)+1,LEN(E23)),FIND("-",MID(E23,FIND(" ",E23)+1,LEN(E23)))+1),LEN(MID(E23,FIND(" ",E23)+1,LEN(E23)))+1)-FIND("-",MID(E23,FIND(" ",E23)+1,LEN(E23)))-1),"") -> 利息支出 | L23: =IFERROR(MID(MID(E23,FIND(" ",E23)+1,LEN(E23)),FIND("-",MID(E23,FIND(" ",E23)+1,LEN(E23)),FIND("-",MID(E23,FIND(" ",E23)+1,LEN(E23)))+1)+1,LEN(E23)),"") | M23: =IFERROR(IF(H23="1002",1002,VLOOKUP(I23,亿企科目!A:H,6,0)),VLOOKUP(H23,亿企科目!A:G,6,0)) -> 6603 | N23: =IFERROR(IF(H23="1002","银行账户",IF(H23="1123","供应商",VLOOKUP(I23,亿企科目!A:H,8,0))),"") -> 费用项目 | O23: =IF(N23=0,IF(M23="1002",K23,""),_xlfn.TEXTAFTER(E23,"-",-1)) -> 利息支出 | P23: =VLOOKUP(A23,账簿!B:C,2,0) -> 003012 | Q23: =VLOOKUP(P23,账簿!A:B,2,0) -> 昌邑市昌荣城乡建设有限公司 | W23: =X23&AB23&AD23 -> 0030122026-04-213 | X23: =P23 -> 003012 | Y23: =X23 -> 003012 | Z23: =Q23 -> 昌邑市昌荣城乡建设有限公司 | AA23: =LEFT(B23,7) -> 2026-04 | AB23: =B23 -> 2026-04-21 | AC23: 记 | AD23: =VALUE(_xlfn.TEXTAFTER(C23,"-")) -> 3 | AE23: =D23 -> 2026-04-21,昌邑市昌荣城乡建设有限公司,贷款还款 | AF23: 谭雅心 | AG23: 谭雅心 | AN23: =M23 -> 6603 | AP23: =D23 -> 2026-04-21,昌邑市昌荣城乡建设有限公司,贷款还款 | AQ23: CNY | AR23: =F23 -> 133818.93 | AS23: =G23 | AT23: 01 | AU23: * | AV23: 1 | AW23: =AR23 -> 133818.93 | AX23: =AS23 | BQ23: =IF(N23="项目",VLOOKUP(O23,项目!B:C,2,0),IF(K23="空项目",VLOOKUP(K23,项目!B:C,2,0),"")) | BR23: =IFERROR(VLOOKUP(BQ23,项目!A:B,2,0),"") | BU23: =IF(N23="供应商",VLOOKUP(O23,供应商!B:C,2,0),"") | BV23: =IFERROR(VLOOKUP(BU23,供应商!A:B,2,0),"") | BW23: =IF(N23="客户",VLOOKUP(O23,客户!B:C,2,0),"") | BX23: =IFERROR(VLOOKUP(BW23,客户!A:B,2,0),"") | CU23: =IF(N23="费用项目",VLOOKUP(O23,费用项目!B:C,2,0),"") -> 660302 | CV23: =IFERROR(VLOOKUP(CU23,费用项目!A:B,2,0),"") -> 利息支出 | CW23: =IF(N23="银行账户",VLOOKUP(O23,银行变二级!B:C,2,0),"") | CX23: =IFERROR(VLOOKUP(O23,银行变二级!A:B,2,0),"")
A24: 昌邑市昌荣城乡建设有限公司 | B24: 2026-04-21 | C24: 记-003 | D24: 2026-04-21,昌邑市昌荣城乡建设有限公司,贷款还款 | E24: 100203 银行存款-潍坊银行5103 | G24: 133818.93 | H24: =LEFT(E24,4) -> 1002 | I24: =IFERROR(LEFT(E24,FIND(" ",E24)-1),E24) -> 100203 | J24: =LEFT(MID(E24,FIND(" ",E24)+1,LEN(E24)),FIND("-",MID(E24,FIND(" ",E24)+1,LEN(E24))&"-")-1) -> 银行存款 | K24: =IFERROR(MID(MID(E24,FIND(" ",E24)+1,LEN(E24)),FIND("-",MID(E24,FIND(" ",E24)+1,LEN(E24)))+1,IFERROR(FIND("-",MID(E24,FIND(" ",E24)+1,LEN(E24)),FIND("-",MID(E24,FIND(" ",E24)+1,LEN(E24)))+1),LEN(MID(E24,FIND(" ",E24)+1,LEN(E24)))+1)-FIND("-",MID(E24,FIND(" ",E24)+1,LEN(E24)))-1),"") -> 潍坊银行5103 | L24: =IFERROR(MID(MID(E24,FIND(" ",E24)+1,LEN(E24)),FIND("-",MID(E24,FIND(" ",E24)+1,LEN(E24)),FIND("-",MID(E24,FIND(" ",E24)+1,LEN(E24)))+1)+1,LEN(E24)),"") | M24: =IFERROR(IF(H24="1002",1002,VLOOKUP(I24,亿企科目!A:H,6,0)),VLOOKUP(H24,亿企科目!A:G,6,0)) -> 1002 | N24: =IFERROR(IF(H24="1002","银行账户",IF(H24="1123","供应商",VLOOKUP(I24,亿企科目!A:H,8,0))),"") -> 银行账户 | O24: =IF(N24=0,IF(M24="1002",K24,""),_xlfn.TEXTAFTER(E24,"-",-1)) -> 潍坊银行5103 | P24: =VLOOKUP(A24,账簿!B:C,2,0) -> 003012 | Q24: =VLOOKUP(P24,账簿!A:B,2,0) -> 昌邑市昌荣城乡建设有限公司 | W24: =X24&AB24&AD24 -> 0030122026-04-213 | X24: =P24 -> 003012 | Y24: =X24 -> 003012 | Z24: =Q24 -> 昌邑市昌荣城乡建设有限公司 | AA24: =LEFT(B24,7) -> 2026-04 | AB24: =B24 -> 2026-04-21 | AC24: 记 | AD24: =VALUE(_xlfn.TEXTAFTER(C24,"-")) -> 3 | AE24: =D24 -> 2026-04-21,昌邑市昌荣城乡建设有限公司,贷款还款 | AF24: 谭雅心 | AG24: 谭雅心 | AN24: =M24 -> 1002 | AP24: =D24 -> 2026-04-21,昌邑市昌荣城乡建设有限公司,贷款还款 | AQ24: CNY | AR24: =F24 | AS24: =G24 -> 133818.93 | AT24: 01 | AU24: * | AV24: 1 | AW24: =AR24 | AX24: =AS24 -> 133818.93 | BQ24: =IF(N24="项目",VLOOKUP(O24,项目!B:C,2,0),IF(K24="空项目",VLOOKUP(K24,项目!B:C,2,0),"")) | BR24: =IFERROR(VLOOKUP(BQ24,项目!A:B,2,0),"") | BU24: =IF(N24="供应商",VLOOKUP(O24,供应商!B:C,2,0),"") | BV24: =IFERROR(VLOOKUP(BU24,供应商!A:B,2,0),"") | BW24: =IF(N24="客户",VLOOKUP(O24,客户!B:C,2,0),"") | BX24: =IFERROR(VLOOKUP(BW24,客户!A:B,2,0),"") | CU24: =IF(N24="费用项目",VLOOKUP(O24,费用项目!B:C,2,0),"") | CV24: =IFERROR(VLOOKUP(CU24,费用项目!A:B,2,0),"") | CW24: =IF(N24="银行账户",VLOOKUP(O24,银行变二级!B:C,2,0),"") -> 潍坊银行5103 | CX24: =IFERROR(VLOOKUP(O24,银行变二级!A:B,2,0),"") -> 潍坊银行5103
A25: 昌邑市昌荣城乡建设有限公司 | B25: 2026-04-21 | C25: 记-004 | D25: 2026-04-21,昌邑市昌荣城乡建设有限公司,贷款还款 | E25: 220202 应付账款-明细应付款-山东博林供应链管理服务有限公司 | F25: 29708.33 | H25: =LEFT(E25,4) -> 2202 | I25: =IFERROR(LEFT(E25,FIND(" ",E25)-1),E25) -> 220202 | J25: =LEFT(MID(E25,FIND(" ",E25)+1,LEN(E25)),FIND("-",MID(E25,FIND(" ",E25)+1,LEN(E25))&"-")-1) -> 应付账款 | K25: =IFERROR(MID(MID(E25,FIND(" ",E25)+1,LEN(E25)),FIND("-",MID(E25,FIND(" ",E25)+1,LEN(E25)))+1,IFERROR(FIND("-",MID(E25,FIND(" ",E25)+1,LEN(E25)),FIND("-",MID(E25,FIND(" ",E25)+1,LEN(E25)))+1),LEN(MID(E25,FIND(" ",E25)+1,LEN(E25)))+1)-FIND("-",MID(E25,FIND(" ",E25)+1,LEN(E25)))-1),"") -> 明细应付款 | L25: =IFERROR(MID(MID(E25,FIND(" ",E25)+1,LEN(E25)),FIND("-",MID(E25,FIND(" ",E25)+1,LEN(E25)),FIND("-",MID(E25,FIND(" ",E25)+1,LEN(E25)))+1)+1,LEN(E25)),"") -> 山东博林供应链管理服务有限公司 | M25: =IFERROR(IF(H25="1002",1002,VLOOKUP(I25,亿企科目!A:H,6,0)),VLOOKUP(H25,亿企科目!A:G,6,0)) -> 220202 | N25: =IFERROR(IF(H25="1002","银行账户",IF(H25="1123","供应商",VLOOKUP(I25,亿企科目!A:H,8,0))),"") -> 供应商 | O25: =IF(N25=0,IF(M25="1002",K25,""),_xlfn.TEXTAFTER(E25,"-",-1)) -> 山东博林供应链管理服务有限公司 | P25: =VLOOKUP(A25,账簿!B:C,2,0) -> 003012 | Q25: =VLOOKUP(P25,账簿!A:B,2,0) -> 昌邑市昌荣城乡建设有限公司 | W25: =X25&AB25&AD25 -> 0030122026-04-214 | X25: =P25 -> 003012 | Y25: =X25 -> 003012 | Z25: =Q25 -> 昌邑市昌荣城乡建设有限公司 | AA25: =LEFT(B25,7) -> 2026-04 | AB25: =B25 -> 2026-04-21 | AC25: 记 | AD25: =VALUE(_xlfn.TEXTAFTER(C25,"-")) -> 4 | AE25: =D25 -> 2026-04-21,昌邑市昌荣城乡建设有限公司,贷款还款 | AF25: 谭雅心 | AG25: 谭雅心 | AN25: =M25 -> 220202 | AP25: =D25 -> 2026-04-21,昌邑市昌荣城乡建设有限公司,贷款还款 | AQ25: CNY | AR25: =F25 -> 29708.33 | AS25: =G25 | AT25: 01 | AU25: * | AV25: 1 | AW25: =AR25 -> 29708.33 | AX25: =AS25 | BQ25: =IF(N25="项目",VLOOKUP(O25,项目!B:C,2,0),IF(K25="空项目",VLOOKUP(K25,项目!B:C,2,0),"")) | BR25: =IFERROR(VLOOKUP(BQ25,项目!A:B,2,0),"") | BU25: =IF(N25="供应商",VLOOKUP(O25,供应商!B:C,2,0),"") -> 0011769 | BV25: =IFERROR(VLOOKUP(BU25,供应商!A:B,2,0),"") -> 山东博林供应链管理服务有限公司 | BW25: =IF(N25="客户",VLOOKUP(O25,客户!B:C,2,0),"") | BX25: =IFERROR(VLOOKUP(BW25,客户!A:B,2,0),"") | CU25: =IF(N25="费用项目",VLOOKUP(O25,费用项目!B:C,2,0),"") | CV25: =IFERROR(VLOOKUP(CU25,费用项目!A:B,2,0),"") | CW25: =IF(N25="银行账户",VLOOKUP(O25,银行变二级!B:C,2,0),"") | CX25: =IFERROR(VLOOKUP(O25,银行变二级!A:B,2,0),"")
A26: 昌邑市昌荣城乡建设有限公司 | B26: 2026-04-21 | C26: 记-004 | D26: 2026-04-21,昌邑市昌荣城乡建设有限公司,贷款还款 | E26: 100203 银行存款-潍坊银行5103 | G26: 29708.33 | H26: =LEFT(E26,4) -> 1002 | I26: =IFERROR(LEFT(E26,FIND(" ",E26)-1),E26) -> 100203 | J26: =LEFT(MID(E26,FIND(" ",E26)+1,LEN(E26)),FIND("-",MID(E26,FIND(" ",E26)+1,LEN(E26))&"-")-1) -> 银行存款 | K26: =IFERROR(MID(MID(E26,FIND(" ",E26)+1,LEN(E26)),FIND("-",MID(E26,FIND(" ",E26)+1,LEN(E26)))+1,IFERROR(FIND("-",MID(E26,FIND(" ",E26)+1,LEN(E26)),FIND("-",MID(E26,FIND(" ",E26)+1,LEN(E26)))+1),LEN(MID(E26,FIND(" ",E26)+1,LEN(E26)))+1)-FIND("-",MID(E26,FIND(" ",E26)+1,LEN(E26)))-1),"") -> 潍坊银行5103 | L26: =IFERROR(MID(MID(E26,FIND(" ",E26)+1,LEN(E26)),FIND("-",MID(E26,FIND(" ",E26)+1,LEN(E26)),FIND("-",MID(E26,FIND(" ",E26)+1,LEN(E26)))+1)+1,LEN(E26)),"") | M26: =IFERROR(IF(H26="1002",1002,VLOOKUP(I26,亿企科目!A:H,6,0)),VLOOKUP(H26,亿企科目!A:G,6,0)) -> 1002 | N26: =IFERROR(IF(H26="1002","银行账户",IF(H26="1123","供应商",VLOOKUP(I26,亿企科目!A:H,8,0))),"") -> 银行账户 | O26: =IF(N26=0,IF(M26="1002",K26,""),_xlfn.TEXTAFTER(E26,"-",-1)) -> 潍坊银行5103 | P26: =VLOOKUP(A26,账簿!B:C,2,0) -> 003012 | Q26: =VLOOKUP(P26,账簿!A:B,2,0) -> 昌邑市昌荣城乡建设有限公司 | W26: =X26&AB26&AD26 -> 0030122026-04-214 | X26: =P26 -> 003012 | Y26: =X26 -> 003012 | Z26: =Q26 -> 昌邑市昌荣城乡建设有限公司 | AA26: =LEFT(B26,7) -> 2026-04 | AB26: =B26 -> 2026-04-21 | AC26: 记 | AD26: =VALUE(_xlfn.TEXTAFTER(C26,"-")) -> 4 | AE26: =D26 -> 2026-04-21,昌邑市昌荣城乡建设有限公司,贷款还款 | AF26: 谭雅心 | AG26: 谭雅心 | AN26: =M26 -> 1002 | AP26: =D26 -> 2026-04-21,昌邑市昌荣城乡建设有限公司,贷款还款 | AQ26: CNY | AR26: =F26 | AS26: =G26 -> 29708.33 | AT26: 01 | AU26: * | AV26: 1 | AW26: =AR26 | AX26: =AS26 -> 29708.33 | BQ26: =IF(N26="项目",VLOOKUP(O26,项目!B:C,2,0),IF(K26="空项目",VLOOKUP(K26,项目!B:C,2,0),"")) | BR26: =IFERROR(VLOOKUP(BQ26,项目!A:B,2,0),"") | BU26: =IF(N26="供应商",VLOOKUP(O26,供应商!B:C,2,0),"") | BV26: =IFERROR(VLOOKUP(BU26,供应商!A:B,2,0),"") | BW26: =IF(N26="客户",VLOOKUP(O26,客户!B:C,2,0),"") | BX26: =IFERROR(VLOOKUP(BW26,客户!A:B,2,0),"") | CU26: =IF(N26="费用项目",VLOOKUP(O26,费用项目!B:C,2,0),"") | CV26: =IFERROR(VLOOKUP(CU26,费用项目!A:B,2,0),"") | CW26: =IF(N26="银行账户",VLOOKUP(O26,银行变二级!B:C,2,0),"") -> 潍坊银行5103 | CX26: =IFERROR(VLOOKUP(O26,银行变二级!A:B,2,0),"") -> 潍坊银行5103
A27: 昌邑市昌荣城乡建设有限公司 | B27: 2026-04-30 | C27: 记-005 | D27: 支付金融利息支出,2026-03-24,26372000001300613776,利息收入,山东博林供应链管理服务有限公司;支付金融利息支出,2026-02-28,26372000000872431306,利息收入,山东博林供应链管理服务有限公司;支付金融利息支出,2026-01-28,26372000000431276296,利息收入,山东博林供应链管理服务有限公司 | E27: 6603 财务费用-利息支出 | F27: 86249.99 | H27: =LEFT(E27,4) -> 6603 | I27: =IFERROR(LEFT(E27,FIND(" ",E27)-1),E27) -> 6603 | J27: =LEFT(MID(E27,FIND(" ",E27)+1,LEN(E27)),FIND("-",MID(E27,FIND(" ",E27)+1,LEN(E27))&"-")-1) -> 财务费用 | K27: =IFERROR(MID(MID(E27,FIND(" ",E27)+1,LEN(E27)),FIND("-",MID(E27,FIND(" ",E27)+1,LEN(E27)))+1,IFERROR(FIND("-",MID(E27,FIND(" ",E27)+1,LEN(E27)),FIND("-",MID(E27,FIND(" ",E27)+1,LEN(E27)))+1),LEN(MID(E27,FIND(" ",E27)+1,LEN(E27)))+1)-FIND("-",MID(E27,FIND(" ",E27)+1,LEN(E27)))-1),"") -> 利息支出 | L27: =IFERROR(MID(MID(E27,FIND(" ",E27)+1,LEN(E27)),FIND("-",MID(E27,FIND(" ",E27)+1,LEN(E27)),FIND("-",MID(E27,FIND(" ",E27)+1,LEN(E27)))+1)+1,LEN(E27)),"") | M27: =IFERROR(IF(H27="1002",1002,VLOOKUP(I27,亿企科目!A:H,6,0)),VLOOKUP(H27,亿企科目!A:G,6,0)) -> 6603 | N27: =IFERROR(IF(H27="1002","银行账户",IF(H27="1123","供应商",VLOOKUP(I27,亿企科目!A:H,8,0))),"") -> 费用项目 | O27: =IF(N27=0,IF(M27="1002",K27,""),_xlfn.TEXTAFTER(E27,"-",-1)) -> 利息支出 | P27: =VLOOKUP(A27,账簿!B:C,2,0) -> 003012 | Q27: =VLOOKUP(P27,账簿!A:B,2,0) -> 昌邑市昌荣城乡建设有限公司 | W27: =X27&AB27&AD27 -> 0030122026-04-305 | X27: =P27 -> 003012 | Y27: =X27 -> 003012 | Z27: =Q27 -> 昌邑市昌荣城乡建设有限公司 | AA27: =LEFT(B27,7) -> 2026-04 | AB27: =B27 -> 2026-04-30 | AC27: 记 | AD27: =VALUE(_xlfn.TEXTAFTER(C27,"-")) -> 5 | AE27: =D27 -> 支付金融利息支出,2026-03-24,26372000001300613776,利息收入,山东博林供应链管理服务有限公司;支付金融利息支出,2026-02-28,26372000000872431306,利息收入,山东博林供应链管理服务有限公司;支付金融利息支出,2026-01-28,26372000000431276296,利息收入,山东博林供应链管理服务有限公司 | AF27: 谭雅心 | AG27: 谭雅心 | AN27: =M27 -> 6603 | AP27: =D27 -> 支付金融利息支出,2026-03-24,26372000001300613776,利息收入,山东博林供应链管理服务有限公司;支付金融利息支出,2026-02-28,26372000000872431306,利息收入,山东博林供应链管理服务有限公司;支付金融利息支出,2026-01-28,26372000000431276296,利息收入,山东博林供应链管理服务有限公司 | AQ27: CNY | AR27: =F27 -> 86249.99 | AS27: =G27 | AT27: 01 | AU27: * | AV27: 1 | AW27: =AR27 -> 86249.99 | AX27: =AS27 | BQ27: =IF(N27="项目",VLOOKUP(O27,项目!B:C,2,0),IF(K27="空项目",VLOOKUP(K27,项目!B:C,2,0),"")) | BR27: =IFERROR(VLOOKUP(BQ27,项目!A:B,2,0),"") | BU27: =IF(N27="供应商",VLOOKUP(O27,供应商!B:C,2,0),"") | BV27: =IFERROR(VLOOKUP(BU27,供应商!A:B,2,0),"") | BW27: =IF(N27="客户",VLOOKUP(O27,客户!B:C,2,0),"") | BX27: =IFERROR(VLOOKUP(BW27,客户!A:B,2,0),"") | CU27: =IF(N27="费用项目",VLOOKUP(O27,费用项目!B:C,2,0),"") -> 660302 | CV27: =IFERROR(VLOOKUP(CU27,费用项目!A:B,2,0),"") -> 利息支出 | CW27: =IF(N27="银行账户",VLOOKUP(O27,银行变二级!B:C,2,0),"") | CX27: =IFERROR(VLOOKUP(O27,银行变二级!A:B,2,0),"")
